<mujoco model="MyoArm_v0.01">
<!-- =================================================
    Copyright 2020 Vikash Kumar, Vittorio Caggiano, Guillaume Durandau
    Model   :: Myo Hand (MuJoCoV2.0)
    Author  :: Vikash Kumar (vikashplus@gmail.com), Vittorio Caggiano, Huawei Wang
    source  :: https://github.com/vikashplus
    License :: Under Apache License, Version 2.0 (the "License"); you may not use this file except in compliance with the License. You may obtain a copy of the License at http://www.apache.org/licenses/LICENSE-2.0 Unless required by applicable law or agreed to in writing, software distributed under the License is distributed on an "AS IS" BASIS, WITHOUT WARRANTIES OR CONDITIONS OF ANY KIND, either express or implied. See the License for the specific language governing permissions and limitations under the License.
====================================================== -->

    <include file="../../../../simhive/myo_sim/arm/assets/myoarm_assets.xml"/>
    <include file="../../../../simhive/myo_sim/scene/myosuite_scene.xml"/>
    <compiler meshdir='../../../../simhive/myo_sim/' texturedir='../../../../simhive/myo_sim/'/>

    <asset>
        <mesh file="../myo_sim/meshes/human_lowpoly_norighthand.stl" name="body_norighthand"/>
        <texture name="tabletop" type="2d" file="../furniture_sim/common/textures/stone1.png"/>
        <material name="tabletop" texture="tabletop" rgba=".95 .95 .95 1"/>
        <texture name="texwood" type="cube" file="../myo_sim/scene/floor0.png"/>
        <material name="matwood" reflectance="0.01" texture="texwood" texuniform="false"/>
    </asset>

    <worldbody>

        <!-- ======= MyoArm ======= -->
        <geom name="body" type="mesh" mesh="body_norighthand" euler="0 0 3.14" contype="0" conaffinity="0"/>
        <body name="full_body" pos="-.025 0.1 1.40">
            <include file="../../../../simhive/myo_sim/arm/assets/myoarm_body.xml"/>
        </body>

        <!-- ======= Table ======= -->
        <body name="table" pos="0 -.5 .85">
            <geom name="table_top" type="box" size=".8 .5 .05" contype="1" conaffinity="1" material="tabletop"/>
            <geom name="table_base" type="box" size=".35 .6 .45" pos="0 0 -.45" euler="0 0 1.57" contype="1" conaffinity="1" material="matwood"/>
        </body>

        <!-- ======= Object ======= -->
        <body name="Object" pos="0 -.25 .95">
            <joint name="OBJTx" pos="0 0 0" axis="1 0 0" limited="true" type="slide" range="-1.20 1.55" damping="0.001" />
            <joint name="OBJTy" pos="0 0 0" axis="0 1 0" limited="true" type="slide" range="-1.10 1.20" damping="0.001" />
            <joint name="OBJTz" pos="0 0 0" axis="0 0 1" limited="true" type="slide" range="-1.10 1.35" damping="0.001" />
            <joint name="OBJRx" pos="0 0 0  " axis="1 0 0" limited="false" damping="0.001" />
            <joint name="OBJRy" pos="0 0 0" axis="0 1 0" limited="false" damping="0.001" />
            <joint name="OBJRz" pos="0 0 0" axis="0 0 1" limited="false" damping="0.001" />
            <geom type="box" size="0.0284 0.0284 0.0284" euler="0.001 0.001 0.001" condim="4" rgba=".5 .2 .7 1" contype="1" conaffinity="1"/>
            <geom type="box" size="0.00284 0.00284 0.00284" euler="0.001 0.001 0.001" condim="4" rgba=".5 .2 .7 1" contype="1" conaffinity="1"/> <!-- dummy geom for creating different objects-->
            <geom type="box" size="0.00284 0.00284 0.00284" euler="0.001 0.001 0.001" condim="4" rgba=".5 .2 .7 1" contype="1" conaffinity="1"/> <!-- dummy geom for creating different objects-->
            <site name="object_o" type="sphere" size="0.005" rgba="0.8 0.8 0.8 0.8" group="4" pos="0 0 0" />
            <site name="object_x" type="sphere" size="0.005" rgba="0.8 0.2 0.2 0.8" group="4" pos="0.028 0 0" />
            <site name="object_y" type="sphere" size="0.005" rgba="0.2 0.8 0.2 0.8" group="4" pos="0 .028 0" />
            <site name="object_z" type="sphere" size="0.005" rgba="0.2 0.2 0.8 0.8" group="4" pos="0 0 .028" />
        </body>

        <!-- ======= BIN ======= -->
        <body name="target" pos="0 -.25 0.9" euler="0.001 0.001 0.001" mocap="true">
            <!-- <geom name="target_dice" type="box" size="0.026 0.026 0.026" contype="0" conaffinity="0" rgba='.1 1 .1 .3' group="2" /> -->
            <geom name="base" type="box" size="0.10 0.10 0.10" pos="0.0 0.0 -.09" contype="1" conaffinity="1" group="2" material="matwood"/>
            <geom name="wall0" type="box" size="0.10 0.01 0.10" pos="0 0.091 0.1" contype="1" conaffinity="1" group="2" material="matwood"/>
            <geom name="wall1" type="box" size="0.01 0.10 0.10" pos="0.091 0 0.1" contype="1" conaffinity="1" group="2" material="matwood"/>
            <geom name="wall2" type="box" size="0.10 0.01 0.10" pos="0 -.091 0.1" contype="1" conaffinity="1" group="2" material="matwood"/>
            <geom name="wall3" type="box" size="0.01 0.10 0.10" pos="-.091 0 0.1" contype="1" conaffinity="1" group="2" material="matwood"/>

            <site name="target_ball" type="sphere" size="0.045" rgba="0.2 1.7 0.2 0.1"/>
            <site name="target_o" type="sphere" size="0.005" rgba="0.8 0.8 0.8 0.8" group="4" pos="0 0 0" />
            <site name="target_x" type="sphere" size="0.005" rgba="0.8 0.2 0.2 0.8" group="4" pos="0.03 0 0" />
            <site name="target_y" type="sphere" size="0.005" rgba="0.2 0.8 0.2 0.8" group="4" pos="0 .03 0" />
            <site name="target_z" type="sphere" size="0.005" rgba="0.2 0.2 0.8 0.8" group="4" pos="0 0 .03" />
        </body>

    </worldbody>

    <keyframe>
        <key qpos='-0.022856 0.00967764 -0.00968029 0.10125 -0.00458344 0.20262 0.0828 -0.0168106 -0.2149 0.03876 0.168055 0.17281 -0.254074 -0.109975 1.11181 0.92689 0.106468 0 0.332 0.4114 -0.177165 -0.26182 0.18852 0.17017 0.447735 0.26707 0.28278 -0.010472 0.0168535 0.00701979 0.09139 -0.06545 0.243505 0.337765 0.23565 -0.101844 0.000607067 0.03142 -.2 0 -0.02 0 0 0'/>
        <key qpos='-0.022856 0.01113 -0.08268 0.10125 -0.0494 0.16578 0.11868 -0.1932 -0.19648 0.03876 0.168055 0.17281 -0.254074 -0.109975 1.47485 1.28822 0.106468 -0.27489 0.332 0.4114 -0.177165 -0.26182 0.18852 0.17017 0.447735 0.26707 0.28278 -0.010472 0.0168535 0.00701979 0.09139 -0.06545 0.243505 0.337765 0.23565 -0.101844 0.000607067 0.03142 -0.2 0 -0.02 0 0 0'/>
    </keyframe>
</mujoco>