<mujoco model="ping_pong_paddle">
    <include file="../../../simhive/myo_sim/torso/assets/myotorso_arm_assets.xml"/>
    <include file="../../../simhive/myo_sim/arm/assets/myoarm_assets.xml"/>
    
    <asset>
        <!-- Ping Pong mesh and texture -->
        <mesh name="pingpong_table" file="C:\Users\chery\Downloads\myosuite\myosuite\envs\myo\assets\table_tennis\pingpong_table.obj" />
        <mesh name="pingpong_net_mesh" file="C:\Users\chery\Downloads\myosuite\myosuite\envs\myo\assets\table_tennis\pingpong_net.obj" />
        <texture name="pingpong_tex" type="2d" file="C:\Users\chery\Downloads\myosuite\myosuite\envs\myo\assets\table_tennis\PingPong.png"/>
        
        <material name="pingpong_mat" texture="pingpong_tex" specular="0.2" shininess="0.4"/>

        <!-- Ping Pong Paddle mesh and texture -->
        <mesh name="ping_pong_paddle_mesh" file="C:\Users\chery\Downloads\myosuite\myosuite\envs\myo\assets\table_tennis\Ping_Pong_Paddle.obj" />
        <texture name="paddle_tex" type="2d" file="C:\Users\chery\Downloads\myosuite\myosuite\envs\myo\assets\table_tennis\paddle_1k.png"/>
        <material name="paddle_mat" texture="paddle_tex" specular="0.2" shininess="0.4"/>

        <!-- Floor material -->
        <material name="floor_mat" rgba="0.3 0 0 1"/>
    </asset>

    <default class="main">
        <default class="visual">
            <geom group="2" type="mesh" contype="0" conaffinity="0"/>
        </default>
        <default class="collision">
            <geom group="3" type="mesh" condim="3" />
        </default>
    </default>

    <compiler autolimits = "true" inertiafromgeom="auto" angle="radian" balanceinertia="true" boundmass="0.001" boundinertia=".0001" />
    <option timestep="0.002">
        <flag multiccd="enable"/>
    </option>
    
    <worldbody>
        <!-- Floor geom -->
        <geom name="floor" type="plane" size="5 4 0.01" pos="0 0 -0.01" material="floor_mat"/>
        <body name="full_body" pos="1.525 0.2 0.95" euler="0 0 3.14">
            <include file="../../../simhive/myo_sim/torso/assets/myotorso_arm_chain.xml"/>
            <joint name="pelvis_x" type="slide" axis="1 0 0" damping="10000" range="-1 -0.05"/>
            <joint name="pelvis_y" type="slide" axis="0 1 0" damping="10000" range="-1 1"/>
            <include file="../../../simhive/myo_sim/leg/assets/myolegs_chain.xml"/>
        </body>
        <!-- Ping Pong geom -->
        <geom name="ping_pong_table" type="mesh" mesh="pingpong_table"
              material="pingpong_mat" rgba="1 1 1 1"
              pos="0 0 0" euler="1.57 0 0"/>
        <geom name="ping_pong_net" type="mesh" mesh="pingpong_net_mesh"
              material="pingpong_mat" rgba="1 1 1 1"
              pos="0 0 0" euler="1.57 0 0"/>  

        <!--body name="ping_pong_paddle_free" pos="1 0 1.1" euler="0 0 0">
            <inertial pos="0 0 0" mass="0.1" diaginertia="0.001 0.001 0.001"/>
            <geom name="ping_pong_paddle" type="mesh" mesh="ping_pong_paddle_mesh"
                material="paddle_mat" rgba="1 1 1 1"
                pos="0 0 0" euler="0 0 0" class="visual"/>
            <geom name="pad" type="cylinder" size="0.082 0.01" pos="-0.07 0 0" class="collision"/>
            <geom name="handle" type="cylinder" euler="0 90 0" size="0.016 0.051" pos="0.04 0 0" class="collision"/>
            <freejoint/>
        </body>-->

        <body name="ball" pos="0.5 0.0 1.052">
            <inertial pos="0 0 0" mass="2.7e-3" diaginertia="0.00000072 0.00000072 0.00000072"/>
            <freejoint/>
            <geom name="geom_ball" size=".02" shellinertia="false" fluidcoef="0.235 0.25 0.0 1.0 1.0" group="1" rgba="0.98 0.70 0.015 1" solref="-100000 -0" fluidshape="ellipsoid"/>
        </body>

        <!-- Spotlights -->
        <light name="spotlight1" pos="1 1 3" dir="-1 -1 -3" cutoff="30" exponent="5" castshadow="true"/>
        <light name="spotlight2" pos="-1 -1 3" dir="1 1 -3" cutoff="30" exponent="5" castshadow="true"/>
    </worldbody>

    </mujoco>
