<mujoco model="banana">
    <include file="../../../../simhive/object_sim/common_extra.xml"/>
    <include file="../../../../simhive/myo_sim/hand/assets/myo_hand_assets.xml"/>
    <include file="../../../../simhive/myo_sim/scene/myosuite_scene.xml"/>
    <compiler meshdir='../../../../simhive/object_sim/' texturedir='../../../../simhive/object_sim/'/>

    <default>
		<default class="banana">
			<geom contype="1" conaffinity="1" condim="3" material="MatSkin"/>
            <site group="3"/>
		</default>
    </default>

    <asset>
        <mesh name="banana" file="banana/banana.stl" scale='.7 .7 .7'/>
        <mesh name="contact0" file="banana/contact0.stl" scale='.7 .7 .7'/>
        <mesh name="contact1" file="banana/contact1.stl" scale='.7 .7 .7'/>
        <mesh name="contact2" file="banana/contact2.stl" scale='.7 .7 .7'/>
        <mesh name="contact3" file="banana/contact3.stl" scale='.7 .7 .7'/>
        <mesh name="contact4" file="banana/contact4.stl" scale='.7 .7 .7'/>
    </asset>

    <worldbody>
        <include file="../../../../simhive/myo_sim/hand/assets/myo_hand_body.xml"/>
        <camera name='front' pos="-.072 -1.230 1.6" euler='1.35 0 0'/>
        <site name="eps_ball" type="sphere" pos="-.230 -.530 1.445" size="0.08" rgba="1 1 0 0" group="1"/>

        <body childclass="banana" name="Object" pos="-.238 -.532 1.455" user="1001 0 2003 27 0 0 0.06 0 0" euler="0 0 0">
            <joint name="OBJTx" pos="0 0 0" axis="1 0 0" type="slide" limited="false" damping="0" />
            <joint name="OBJTy" pos="0 0 0" axis="0 1 0" type="slide" limited="false" damping="0" />
            <joint name="OBJTz" pos="0 0 0" axis="0 0 1" type="slide" limited="false" damping="0" />
            <joint name="OBJRx" pos="0 0 0" axis="1 0 0" limited="false" damping="0" />
            <joint name="OBJRy" pos="0 0 0" axis="0 1 0" limited="false" damping="0" />
            <joint name="OBJRz" pos="0 0 0" axis="0 0 1" limited="false" damping="0" />

            <geom name="banana_visual" mesh="banana" class='object_visual' rgba="1 1 0 1.0"/>
            <geom name="banana_contact0" mesh="contact0" class="object_contact"/>
            <geom name="banana_contact1" mesh="contact1" class="object_contact"/>
            <geom name="banana_contact2" mesh="contact2" class="object_contact"/>
            <geom name="banana_contact3" mesh="contact3" class="object_contact"/>
            <geom name="banana_contact4" mesh="contact4" class="object_contact"/>

            <site name="object_top" type="sphere" size="0.005" rgba="0.8 0.2 0.2 1" pos="0 0 0.065" />
            <site name="object_bottom" type="sphere" size="0.005" rgba="0.2 0.8 0.2 1" pos="0 0 -0.065" />

            <geom name="top" type="cylinder" size="0.013 0.002" condim="4" pos="0 0 -.035" rgba="0 .5 1 0" contype="0" conaffinity="0"/>
            <geom name="bot" type="cylinder" size="0.013 0.002" pos="0 0 0.035" rgba="0 .5 1 0" contype="0" conaffinity="0"/>
        </body>

        <!-- <body childclass="banana" name="target" pos="0 -.54 1.455" > -->
        <body childclass="banana" name="target" pos="-.238 -.532 1.650" >
            <site name="target_top" type="sphere" size="0.005" rgba="0.8 0.2 0.2 1" pos="0 0 0.065" />
            <site name="target_bottom" type="sphere" size="0.005" rgba="0.2 0.8 0.2 1" pos="0 0 -0.065" />

            <geom name="t_banana_visual" mesh="banana" class="object_visual" rgba="1 1 0 1.0"/>
            <geom name="t_banana_contact0" mesh="contact0" class="object_contact"/>
            <geom name="t_banana_contact1" mesh="contact1" class="object_contact"/>
            <geom name="t_banana_contact2" mesh="contact2" class="object_contact"/>
            <geom name="t_banana_contact3" mesh="contact3" class="object_contact"/>
            <geom name="t_banana_contact4" mesh="contact4" class="object_contact"/>

            <geom name="t_top" type="cylinder" size="0.013 0.002" condim="4" pos="0 0 -.035" rgba="0 .5 1 0" contype="0" conaffinity="0"/>
            <geom name="t_bot" type="cylinder" size="0.013 0.002" pos="0 0 0.035" rgba="0 .5 1 0" contype="0" conaffinity="0"/>
        </body>
    </worldbody>
</mujoco>
