<mujoco model="MyoHand TableTop">
<!-- =================================================
    Copyright 2020 Vikash Kumar
    Model   :: MyoHand TableTop (MuJoCoV2.1)
    Author  :: Vittorio Caggiano (caggiano@gmail.com), Vikash Kumar (vikashplus@gmail.com), Sudeep Dasari (sdasari@andrew.cmu.edu )
    Source  :: https://github.com/vikashplus/robohive
    License :: Under Apache License, Version 2.0 (the "License"); you may not use this file except in compliance with the License. You may obtain a copy of the License at http://www.apache.org/licenses/LICENSE-2.0 Unless required by applicable law or agreed to in writing, software distributed under the License is distributed on an "AS IS" BASIS, WITHOUT WARRANTIES OR CONDITIONS OF ANY KIND, either express or implied. See the License for the specific language governing permissions and limitations under the License.
====================================================== -->

    <include file="myohand_tabletop.xml"/>
    <include file="../../../../simhive/object_sim/common.xml"/>
    <include file="../../../../simhive/object_sim/OBJECT_NAME/assets.xml"/>

    <worldbody>
        <!-- <body name="OBJECT_NAME" pos="0.00 0.0 .045" childclass="grab"> -->
        <body name="OBJECT_NAME" pos="0.00 0.0 .035" childclass="grab">
            <joint name="OBJTx" pos="0 0 0" axis="1 0 0" type="slide"/>
            <joint name="OBJTy" pos="0 0 0" axis="0 1 0" type="slide"/>
            <joint name="OBJTz" pos="0 0 0" axis="0 0 1" type="slide"/>
            <joint name="OBJRx" pos="0 0 0" axis="1 0 0"/>
            <joint name="OBJRy" pos="0 0 0" axis="0 1 0"/>
            <joint name="OBJRz" pos="0 0 0" axis="0 0 1"/>
            <include file="../../../../simhive/object_sim/OBJECT_NAME/body.xml"/>
        </body>
    </worldbody>

</mujoco>
