<mujoco model="MyoHand model - Index Thumb Model for turning key task">
<!-- =================================================
	Copyright 2020 Vikash Kumar
	Model	:: MyoHand (MuJoCoV2.0)
	Author	:: Vikash Kumar (vikashplus@gmail.com)
	source	:: https://github.com/vikashplus
	License	:: Under Apache License, Version 2.0 (the "License"); you may not use this file except in compliance with the License. You may obtain a copy of the License at http://www.apache.org/licenses/LICENSE-2.0 Unless required by applicable law or agreed to in writing, software distributed under the License is distributed on an "AS IS" BASIS, WITHOUT WARRANTIES OR CONDITIONS OF ANY KIND, either express or implied. See the License for the specific language governing permissions and limitations under the License.
====================================================== -->

    <include file="../../../../simhive/myo_sim/hand/assets/myohand_assets.xml"/>
    <include file="../../../../simhive/myo_sim/scene/myosuite_scene.xml"/>
    <compiler meshdir='../../../../simhive/myo_sim/' texturedir='../../../../simhive/myo_sim/'/>

    <default>
        <default class="key">
            <geom rgba=".6 .6 .5 1"/>
        </default>
    </default>

    <worldbody>
        <include file="../../../../simhive/myo_sim/hand/assets/myohand_body.xml"/>
        <body name="key" pos="-.15 -.55 1.425" childclass="key" euler="0 0 2.2">
            <geom type="ellipsoid" size=".030 .030 .004" name="keyhead"/>
            <site type="sphere" size=".03" rgba=".5 .7 .8 .3"/>
            <geom type="capsule" size="0.005 0.070" pos="-.045 0 0" euler="0 1.57 0"/>
            <geom type="box" size=".015 .010 .004" pos="-.1 0.008 0"/>
            <joint name="keyjoint" axis="1 0 0" type="hinge" frictionloss="0.02" damping=".1"/>
            <site name="keyhead" size="0.005"/>
        </body>
    </worldbody>

    <!-- <keyframe>
        <key qpos='-0.017455 -0.174595 0.865249 0.882818 0.182 -0.031352 -0.17 0.592621 0'/>
    </keyframe> -->
</mujoco>