<mujocoinclude model="MyoTorso">
  <!-- =================================================
  Copyright (c) MyoSuite Authors
  Model	:: MyoTorso (MuJoCoV3.0)
  Author	::  Rohan Walia, Morgane Billot, Kevin Garzon-Aguirre, Swathika Subramanian, Huiyi Wang,
                 Mohamed Irfan Refai, Guillaume Durandau, Vikash Kumar (vikashplus@gmail.com), Vittorio Caggiano
  License	:: Under Apache License, Version 2.0 (the "License"); you may not use this file except in compliance with the License. You may obtain a copy of the License at http://www.apache.org/licenses/LICENSE-2.0 Unless required by applicable law or agreed to in writing, software distributed under the License is distributed on an "AS IS" BASIS, WITHOUT WARRANTIES OR CONDITIONS OF ANY KIND, either express or implied. See the License for the specific language governing permissions and limitations under the License.
  ====================================================== -->
    <body name="sacrum" pos="0 0 0" quat="0.707035 0.707179 0 0" childclass="myotorso">
      <inertial pos="0 0 0" quat="0.707107 0 0 0.707107" mass="7.486" diaginertia="0.08 0.075 0.03"/>

      <!-- pelvis sites -->
      <site name="Ps_L1_VB_r_Ps_L1_VB_r-P2" pos="-0.0238 -0.057 0.0759"/>
      <site name="Ps_L1_TP_r_Ps_L1_TP_r-P2" pos="-0.0238 -0.057 0.0759"/>
      <site name="Ps_L1_L2_IVD_r_Ps_L1_L2_IVD_r-P2" pos="-0.0238 -0.057 0.0759"/>
      <site name="Ps_L2_TP_r_Ps_L2_TP_r-P2" pos="-0.0238 -0.057 0.0759"/>
      <site name="Ps_L2_L3_IVD_r_Ps_L2_L3_IVD_r-P2" pos="-0.0238 -0.057 0.0759"/>
      <site name="Ps_L3_TP_r_Ps_L3_TP_r-P2" pos="-0.0238 -0.057 0.0759"/>
      <site name="Ps_L3_L4_IVD_r_Ps_L3_L4_IVD_r-P2" pos="-0.0238 -0.057 0.0759"/>
      <site name="Ps_L4_TP_r_Ps_L4_TP_r-P2" pos="-0.0238 -0.057 0.0759"/>
      <site name="Ps_L4_L5_IVD_r_Ps_L4_L5_IVD_r-P2" pos="-0.0238 -0.057 0.0759"/>
      <site name="Ps_L5_TP_r_Ps_L5_TP_r-P2" pos="-0.0238 -0.057 0.0759"/>
      <site name="Ps_L5_VB_r_Ps_L5_VB_r-P2" pos="-0.0238 -0.057 0.0759"/>
      <site name="Ps_L1_VB_l_Ps_L1_VB_l-P2" pos="-0.0238 -0.057 -0.0759"/>
      <site name="Ps_L1_TP_l_Ps_L1_TP_l-P2" pos="-0.0238 -0.057 -0.0759"/>
      <site name="Ps_L1_L2_IVD_l_Ps_L1_L2_IVD_l-P2" pos="-0.0238 -0.057 -0.0759"/>
      <site name="Ps_L2_TP_l_Ps_L2_TP_l-P2" pos="-0.0238 -0.057 -0.0759"/>
      <site name="Ps_L2_L3_IVD_l_Ps_L2_L3_IVD_l-P2" pos="-0.0238 -0.057 -0.0759"/>
      <site name="Ps_L3_TP_l_Ps_L3_TP_l-P2" pos="-0.0238 -0.057 -0.0759"/>
      <site name="Ps_L3_L4_IVD_l_Ps_L3_L4_IVD_l-P2" pos="-0.0238 -0.057 -0.0759"/>
      <site name="Ps_L4_TP_l_Ps_L4_TP_l-P2" pos="-0.0238 -0.057 -0.0759"/>
      <site name="Ps_L4_L5_IVD_l_Ps_L4_L5_IVD_l-P2" pos="-0.0238 -0.057 -0.0759"/>
      <site name="Ps_L5_TP_l_Ps_L5_TP_l-P2" pos="-0.0238 -0.057 -0.0759"/>
      <site name="Ps_L5_VB_l_Ps_L5_VB_l-P2" pos="-0.0238 -0.057 -0.0759"/>
      <site name="rect_abd_r_rect_abd_r-P1" pos="-0.0415823 -0.0964762 -0.0106888"/>
      <site name="rect_abd_l_rect_abd_l-P1" pos="-0.04158 -0.09648 0.01069"/>
      <site name="IL_L1_r_IL_L1_r-P1" pos="-0.15941 0.0109456 0.0382937"/>
      <site name="IL_L2_r_IL_L2_r-P1" pos="-0.150919 0.0281772 0.0426489"/>
      <site name="IL_L3_r_IL_L3_r-P1" pos="-0.13692 0.0398108 0.047511"/>
      <site name="IL_L4_r_IL_L4_r-P1" pos="-0.131838 0.0365973 0.0442041"/>
      <site name="IL_L1_l_IL_L1_l-P1" pos="-0.15941 0.0109456 -0.0382937"/>
      <site name="IL_L2_l_IL_L2_l-P1" pos="-0.150919 0.0281772 -0.0426489"/>
      <site name="IL_L3_l_IL_L3_l-P1" pos="-0.13692 0.0398108 -0.047511"/>
      <site name="IL_L4_l_IL_L4_l-P1" pos="-0.131838 0.0365973 -0.0442041"/>
      <site name="IL_R5_r_IL_r5_R-P1" pos="-0.156297 0.0143181 0.0389721"/>
      <site name="IL_R6_r_IL_r6_R-P1" pos="-0.14525 0.0310082 0.042568"/>
      <site name="IL_R7_r_IL_r7_R-P1" pos="-0.134159 0.0383563 0.0458664"/>
      <site name="IL_R8_r_IL_r8_R-P1" pos="-0.137327 0.0429011 0.0501801"/>
      <site name="IL_R9_r_IL_r9_R-P1" pos="-0.13331 0.0448841 0.0511394"/>
      <site name="IL_R10_r_IL_r10_R-P1" pos="-0.130303 0.04775 0.0531086"/>
      <site name="IL_R11_r_IL_r11_R-P1" pos="-0.127464 0.0499569 0.0554708"/>
      <site name="IL_R12_r_IL_r12_R-P1" pos="-0.124813 0.0521242 0.0579249"/>
      <site name="IL_R5_l_IL_r5_R-P1" pos="-0.156297 0.0143181 -0.03897"/>
      <site name="IL_R6_l_IL_r6_R-P1" pos="-0.14525 0.0310082 -0.04257"/>
      <site name="IL_R7_l_IL_r7_R-P1" pos="-0.134159 0.0383563 -0.04587"/>
      <site name="IL_R8_l_IL_r8_R-P1" pos="-0.137327 0.0429011 -0.05018"/>
      <site name="IL_R9_l_IL_r9_R-P1" pos="-0.13331 0.0448841 -0.05114"/>
      <site name="IL_R10_l_IL_r10_R-P1" pos="-0.130303 0.04775 -0.05311"/>
      <site name="IL_R11_l_IL_r11_R-P1" pos="-0.127464 0.0499569 -0.05547"/>
      <site name="IL_R12_l_IL_r12_R-P1" pos="-0.124813 0.0521242 -0.05792"/>
      <site name="LTpL_L4_r_pathpoint" pos="-0.150501 0.0174866 0.0373097"/>
      <site name="LTpL_L3_r_pathpoint" pos="-0.158442 0.01749 0.0402"/>
      <site name="LTpL_L2_r_pathpoint" pos="-0.159688 0.0129688 0.0419459"/>
      <site name="LTpL_L1_r_pathpoint" pos="-0.161991 0.0101936 0.0431168"/>
      <site name="LTpL_L4_l_pathpoint" pos="-0.150501 0.0174866 -0.03731"/>
      <site name="LTpL_L3_l_pathpoint" pos="-0.158442 0.01749 -0.0402"/>
      <site name="LTpL_L2_l_pathpoint" pos="-0.159688 0.0129688 -0.04195"/>
      <site name="LTpL_L1_l_pathpoint" pos="-0.161991 0.01019 -0.04312"/>
      <site name="QL_post_I.1-L3_r_I.1_r-P1" pos="-0.12147 0.04631 0.05202"/>
      <site name="QL_post_I.2-L4_r_I.2_r-P1" pos="-0.11147 0.0563076 0.05902"/>
      <site name="QL_post_I.2-L3_r_I.2_r-P1" pos="-0.11147 0.0563076 0.05902"/>
      <site name="QL_post_I.2-L2_r_I.2_r-P1" pos="-0.11147 0.0563076 0.05902"/>
      <site name="QL_post_I.3-L1_r_I.3_r-P1" pos="-0.10477 0.06212 0.06917"/>
      <site name="QL_post_I.3-L2_r_I.3_r-P1" pos="-0.10477 0.06212 0.06917"/>
      <site name="QL_post_I.3-L3_r_I.3_r-P1" pos="-0.10477 0.06212 0.06917"/>
      <site name="QL_post_I.1-L3_l_I.1_l-P1" pos="-0.12147 0.04631 -0.05202"/>
      <site name="QL_post_I.2-L4_l_I.2_l-P1" pos="-0.11147 0.0563076 -0.05902"/>
      <site name="QL_post_I.2-L3_l_I.2_l-P1" pos="-0.11147 0.0563076 -0.05902"/>
      <site name="QL_post_I.2-L2_l_I.2_l-P1" pos="-0.11147 0.0563076 -0.05902"/>
      <site name="QL_post_I.3-L1_l_I.3_l-P1" pos="-0.10477 0.06212 -0.06917"/>
      <site name="QL_post_I.3-L2_l_I.3_l-P1" pos="-0.10477 0.06212 -0.06917"/>
      <site name="QL_post_I.3-L3_l_I.3_l-P1" pos="-0.10477 0.06212 -0.06917"/>
      <site name="QL_ant_I.2-T12_r_I.2_r-P1" pos="-0.11147 0.0563076 0.05902"/>
      <site name="QL_ant_I.3-T12_r_I.3_r-P1" pos="-0.10477 0.06212 0.06917"/>
      <site name="QL_ant_I.2-12.1_r_I.2_r-P2" pos="-0.11147 0.0563076 0.05902"/>
      <site name="QL_ant_I.3-12.1_r_I.3_r-P1" pos="-0.10477 0.06212 0.06917"/>
      <site name="QL_ant_I.3-12.2_r_I.3_r-P1" pos="-0.10477 0.06212 0.06917"/>
      <site name="QL_ant_I.3-12.3_r_I.3_r-P2" pos="-0.104767 0.0621154 0.06917"/>
      <site name="QL_ant_I.2-T12_l_I.2_l-P1" pos="-0.11147 0.0563076 -0.05902"/>
      <site name="QL_ant_I.3-T12_l_I.3_l-P1" pos="-0.10477 0.06212 -0.06917"/>
      <site name="QL_ant_I.2-12.1_l_I.2_l-P2" pos="-0.11147 0.0563076 -0.05902"/>
      <site name="QL_ant_I.3-12.1_l_I.3_l-P1" pos="-0.10477 0.06212 -0.06917"/>
      <site name="QL_ant_I.3-12.2_l_I.3_l-P1" pos="-0.10477 0.06212 -0.06917"/>
      <site name="QL_ant_I.3-12.3_l_I.3_l-P2" pos="-0.104767 0.0621154 -0.06917"/>
      <site name="MF_m1t.3_r_MF_m1t.3_r-P1" pos="-0.144573 0.0264214 0.0383501"/>
      <site name="MF_m2t.2_r_MF_m2t.2_r-P1" pos="-0.147335 0.0211591 0.0368492"/>
      <site name="MF_m2t.3_r_MF_m2t.3_r-P1" pos="-0.14972 0.00799758 0.0345784"/>
      <site name="MF_m3t.1_r_MF_m3t.1_r-P1" pos="-0.164505 -0.0349768 0.0170996"/>
      <site name="MF_m3t.2_r_MF_m3t.2_r-P1" pos="-0.153875 -0.0160621 0.0218539"/>
      <site name="MF_m3t.3_r_MF_m3t.3_r-P1" pos="-0.153875 -0.0160621 0.0218539"/>
      <site name="MF_m4t.2_r_MF_m4t.2_r-P1" pos="-0.162292 -0.0286577 0.0152036"/>
      <site name="MF_m4t.3_r_MF_m4t.3_r-P1" pos="-0.170828 -0.0411808 0.0127215"/>
      <site name="MF_m5.laminar_r_MF_m5.laminar_r-P1" pos="-0.134206 0.01111 0.01238"/>
      <site name="MF_m1t.3_l_MF_m1t.3_l-P1" pos="-0.144573 0.0264214 -0.03835"/>
      <site name="MF_m2t.2_l_MF_m2t.2_l-P1" pos="-0.147335 0.0211591 -0.03685"/>
      <site name="MF_m2t.3_l_MF_m2t.3_l-P1" pos="-0.14972 0.00799758 -0.03458"/>
      <site name="MF_m3t.1_l_MF_m3t.1_l-P1" pos="-0.164505 -0.0349768 -0.0171"/>
      <site name="MF_m3t.2_l_MF_m3t.2_l-P1" pos="-0.153875 -0.0160621 -0.02185"/>
      <site name="MF_m3t.3_l_MF_m3t.3_l-P1" pos="-0.153875 -0.0160621 -0.02185"/>
      <site name="MF_m4t.2_l_MF_m4t.2_l-P1" pos="-0.162292 -0.0286577 -0.0152"/>
      <site name="MF_m4t.3_l_MF_m4t.3_l-P1" pos="-0.170828 -0.0411808 -0.01272"/>
      <site name="MF_m5.laminar_l_MF_m5.laminar_l-P1" pos="-0.134206 0.01111 -0.01238"/>
      <site name="EO5_r_EO5_r-P2" pos="-0.0592662 0.0594141 0.113816"/>
      <site name="EO6_r_EO6_r-P2" pos="-0.0700762 0.062137 0.104119"/>
      <site name="IO1_r_IO1_r-P2" pos="-0.0256486 0.00060866 0.102457"/>
      <site name="IO2_r_IO2_r-P2" pos="-0.0345887 0.0255669 0.107072"/>
      <site name="IO3_r_IO3_r-P2" pos="-0.0446801 0.046659 0.102425"/>
      <site name="IO4_r_IO4_r-P2" pos="-0.05738 0.0588991 0.110489"/>
      <site name="IO5_r_IO5_r-P2" pos="-0.0848889 0.065154 0.09145"/>
      <site name="IO6_r_IO6_r-P2" pos="-0.1096 0.0608563 0.0696978"/>
      <site name="EO5_l_EO5_l-P2" pos="-0.0592662 0.0594141 -0.11382"/>
      <site name="EO6_l_EO6_l-P2" pos="-0.0700762 0.062137 -0.10412"/>
      <site name="IO1_l_IO1_l-P2" pos="-0.0256486 0.00060866 -0.12246"/>
      <site name="IO2_l_IO2_l-P2" pos="-0.0345887 0.0255669 -0.12707"/>
      <site name="IO3_l_IO3_l-P2" pos="-0.0446801 0.046659 -0.12243"/>
      <site name="IO4_l_IO4_l-P2" pos="-0.05738 0.0588991 -0.11049"/>
      <site name="IO5_l_IO5_l-P2" pos="-0.0848889 0.065154 -0.09145"/>
      <site name="IO6_l_IO6_l-P2" pos="-0.1096 0.0608563 -0.0697"/>
      <!-- lumbar sites -->
      <geom name="sacrum_geom_1" type="mesh" mesh="sacrum_geom_1_sacrum"/>
      <site name="LTpT_T7_r_LTpT_t7_R-P1" pos="-0.131317 0.0605127 0.00027686"/>
      <site name="LTpT_T8_r_LTpT_t8_R-P1" pos="-0.142901 0.0502456 0.00037451"/>
      <site name="LTpT_T9_r_LTpT_t9_R-P1" pos="-0.165822 0.0268352 0"/>
      <site name="LTpT_T10_r_LTpT_t10_R-P1" pos="-0.164463 0.0245611 0.01072"/>
      <site name="LTpT_T11_r_LTpT_t11_R-P1" pos="-0.157649 0.0307094 0.02404"/>
      <site name="LTpT_T12_r_LTpT_t12_R-P1" pos="-0.14476 0.0488 0.02793"/>
      <site name="LTpT_R7_r_LTpT_r7_R-P1" pos="-0.13132 0.06051 0.00028"/>
      <site name="LTpT_R8_r_LTpT_r8_R-P1" pos="-0.1429 0.05025 0.00037"/>
      <site name="LTpT_R9_r_LTpT_r9_R-P1" pos="-0.16582 0.02684 0"/>
      <site name="LTpT_R10_r_LTpT_r10_R-P1" pos="-0.16446 0.02456 0.01072"/>
      <site name="LTpT_R11_r_LTpT_r11_R-P1" pos="-0.15765 0.03071 0.02404"/>
      <site name="LTpT_R12_r_LTpT_r12_R-P1" pos="-0.14476 0.0488 0.02793"/>
      <site name="LTpT_T7_l_LTpT_t7_R-P1" pos="-0.131317 0.0605127 -0.00028"/>
      <site name="LTpT_T8_l_LTpT_t8_R-P1" pos="-0.142901 0.0502456 -0.00037"/>
      <site name="LTpT_T9_l_LTpT_t9_R-P1" pos="-0.165822 0.0268352 0"/>
      <site name="LTpT_T10_l_LTpT_t10_R-P1" pos="-0.164463 0.0245611 -0.01072"/>
      <site name="LTpT_T11_l_LTpT_t11_R-P1" pos="-0.157649 0.0307094 -0.02404"/>
      <site name="LTpT_T12_l_LTpT_t12_R-P1" pos="-0.14476 0.0488 0.02793"/>
      <site name="LTpT_R7_l_LTpT_r7_R-P1" pos="-0.13132 0.06051 -0.00028"/>
      <site name="LTpT_R8_l_LTpT_r8_R-P1" pos="-0.1429 0.05025 -0.00037"/>
      <site name="LTpT_R9_l_LTpT_r9_R-P1" pos="-0.16582 0.02684 0"/>
      <site name="LTpT_R10_l_LTpT_r10_R-P1" pos="-0.16446 0.02456 -0.01072"/>
      <site name="LTpT_R11_l_LTpT_r11_R-P1" pos="-0.15765 0.03071 -0.02404"/>
      <site name="LTpT_R12_l_LTpT_r12_R-P1" pos="-0.14476 0.0488 -0.02793"/>
      <site name="LTpL_L5_r_pathpoint" pos="-0.14125 0.07389 0.03487"/>
      <site name="LTpL_L5_l_pathpoint" pos="-0.14125 0.0738877 -0.034867"/>
      <site name="MF_m1t.2_r_MF_m1t.2_r-P1" pos="-0.121424 0.0839766 0.01884"/>
      <site name="MF_m2t.1_r_MF_m2t.1_r-P1" pos="-0.120758 0.0852181 0.0204354"/>
      <site name="MF_m3s_r_MF_m3s_r-P1" pos="-0.121511 0.0836358 0.0174159"/>
      <site name="MF_m4s_r_MF_m4s_r-P1" pos="-0.143689 0.0547099 0.0161792"/>
      <site name="MF_m4t.1_r_MF_m4t.1_r-P1" pos="-0.152233 0.0415265 0.0153586"/>
      <site name="MF_m5s_r_MF_m5s_r-P1" pos="-0.130455 0.0662703 0.0104264"/>
      <site name="MF_m5t.1_r_MF_m5t.1_r-P1" pos="-0.174067 0.00522922 0.0100331"/>
      <site name="MF_m5t.2_r_MF_m5t.2_r-P1" pos="-0.163116 0.0256618 0.0117079"/>
      <site name="MF_m5t.3_r_MF_m5t.3_r-P1" pos="-0.152276 0.0425844 0.0115967"/>
      <site name="MF_m4.laminar_r_MF_m4.laminar_r-P1" pos="-0.12536 0.0774879 0.01934"/>
      <site name="MF_m1t.2_l_MF_m1t.2_l-P1" pos="-0.121424 0.0839766 -0.01884"/>
      <site name="MF_m2t.1_l_MF_m2t.1_l-P1" pos="-0.120758 0.0852181 -0.02044"/>
      <site name="MF_m3s_l_MF_m3s_l-P1" pos="-0.121511 0.0836358 -0.01742"/>
      <site name="MF_m4s_l_MF_m4s_l-P1" pos="-0.143689 0.0547099 -0.01618"/>
      <site name="MF_m4t.1_l_MF_m4t.1_l-P1" pos="-0.152233 0.0415265 -0.01536"/>
      <site name="MF_m5s_l_MF_m5s_l-P1" pos="-0.130455 0.0662703 -0.01043"/>
      <site name="MF_m5t.1_l_MF_m5t.1_l-P1" pos="-0.174067 0.00522922 -0.01003"/>
      <site name="MF_m5t.2_l_MF_m5t.2_l-P1" pos="-0.163116 0.0256618 -0.01171"/>
      <site name="MF_m5t.3_l_MF_m5t.3_l-P1" pos="-0.152276 0.0425844 -0.0116"/>
      <site name="MF_m4.laminar_l_MF_m4.laminar_l-P1" pos="-0.12536 0.0774879 -0.01934"/>
      <body name="lumbar5" pos="-0.108 0.061 0" euler="0 0 -0.3">
        <inertial pos="0.053744 0.02 0" quat="0.707107 0 0 0.707107" mass="1.824" diaginertia="0.01765 0.01219 0.00546"/>
        <geom name="back_cylinder_s" size="0.07 0.13" pos="-0.118 0.0768 0" class="myoBack_wrap"/>
        <site name="back_cylinder_s_IL_L1_r_1_sidesite" pos="-0.0340058 0.0977894 -0.00109894" class="sidesite"/>
        <site name="back_cylinder_s_IL_L1_l_1_sidesite" pos="-0.0418844 0.112331 -0.0720796" class="sidesite"/>
        <site name="back_cylinder_s_IL_R5_r_1_sidesite" pos="-0.0340043 0.0759544 -0.0125701" class="sidesite"/>
        <site name="back_cylinder_s_IL_R6_r_1_sidesite" pos="-0.0348449 0.0886841 -0.108783" class="sidesite"/>
        <site name="back_cylinder_s_IL_R5_l_1_sidesite" pos="-0.0351706 0.0907744 -0.0594597" class="sidesite"/>
        <site name="back_cylinder_s_IL_R6_l_1_sidesite" pos="-0.0408519 0.110029 -0.0306543" class="sidesite"/>
        <site name="back_cylinder_s_LTpT_R12_r_4_sidesite" pos="-0.0411 0.1048 0.03882" class="sidesite"/>
        <site name="back_cylinder_s_LTpT_R12_r_2_sidesite" pos="-0.03691 0.06919 0.03508" class="sidesite"/>
        <site name="back_cylinder_s_LTpT_R12_r_1_sidesite" pos="-0.03859 0.0494129 0.0902269" class="sidesite"/>
        <site name="back_cylinder_s_LTpT_R12_l_4_sidesite" pos="-0.0411 0.1048 -0.03882" class="sidesite"/>
        <site name="back_cylinder_s_LTpT_R12_l_2_sidesite" pos="-0.03691 0.06919 -0.03508" class="sidesite"/>
        <site name="back_cylinder_s_LTpT_R12_l_1_sidesite" pos="-0.0910785 -0.00276905 0.0534791" class="sidesite"/>
        <site name="back_cylinder_s_LTpL_L1_r_1_sidesite" pos="-0.0370101 0.0990854 -0.0777896" class="sidesite"/>
        <site name="back_cylinder_s_LTpL_L1_l_1_sidesite" pos="-0.0370101 0.0990854 0.0777896" class="sidesite"/>
        <joint name="flex_extension" pos="0 0 0" axis="0 0 1" range="-1.35 0.7538"/>
        <joint name="lat_bending" pos="0 0 0" axis="1 0 0" range="-0.4363 0.4363"/>
        <joint name="axial_rotation" pos="0 0 0" axis="0 1 0" range="-0.7854 0.7854"/>
        <geom name="lumbar5_geom_1" type="mesh" mesh="lumbar5_geom_1_lumbar5"/>
        <site name="Ps_L5_TP_r_Ps_L5_TP_r-P1" pos="-0.00562001 0.0291398 0.0252881"/>
        <site name="Ps_L5_VB_r_Ps_L5_VB_r-P1" pos="0.01 0.01241 0.019"/>
        <site name="Ps_L5_TP_l_Ps_L5_TP_l-P1" pos="-0.00562001 0.0291398 -0.02529"/>
        <site name="Ps_L5_VB_l_Ps_L5_VB_l-P1" pos="0.01 0.01241 -0.019"/>
        <site name="LTpT_T6_r_LTpT_t6_R-P1" pos="-0.03622 0.01615 0.00021356"/>
        <site name="LTpT_R6_r_LTpT_r6_R-P1" pos="-0.03622 0.01615 0.00021"/>
        <site name="LTpT_T6_l_LTpT_t6_R-P1" pos="-0.03622 0.01615 -0.00021"/>
        <site name="LTpT_R6_l_LTpT_r6_R-P1" pos="-0.03622 0.01615 -0.00021"/>
        <site name="LTpL_L5_r_pathpoint_0" pos="-0.0103429 0.02665 0.0224"/>
        <site name="LTpL_L5_l_pathpoint_0" pos="-0.0103429 0.02665 -0.0224"/>
        <site name="MF_m1t.1_r_MF_m1t.1_r-P1" pos="-0.0186347 0.0369697 0.0175946"/>
        <site name="MF_m2s_r_MF_m2s_r-P1" pos="-0.0185029 0.0376762 0.0158123"/>
        <site name="MF_m5s_r_MF_m5s_r-P2" pos="-0.0301638 0.01539 0.00392934"/>
        <site name="MF_m5t.1_r_MF_m5t.1_r-P2" pos="-0.03551 0.016863 0.00292592"/>
        <site name="MF_m5t.2_r_MF_m5t.2_r-P2" pos="-0.0345516 0.0159287 0.00277147"/>
        <site name="MF_m5t.3_r_MF_m5t.3_r-P2" pos="-0.0328228 0.015247 0.00232083"/>
        <site name="MF_m3.laminar_r_MF_m3.laminar_r-P1" pos="-0.0187003 0.0374421 0.01617"/>
        <site name="MF_m5.laminar_r_MF_m5.laminar_-P2" pos="-0.0258996 0.01705 0.00564"/>
        <site name="MF_m1t.1_l_MF_m1t.1_l-P1" pos="-0.0186347 0.0369697 -0.01759"/>
        <site name="MF_m2s_l_MF_m2s_l-P1" pos="-0.0185029 0.0376762 -0.01581"/>
        <site name="MF_m5s_l_MF_m5s_l-P2" pos="-0.0301638 0.01539 -0.00393"/>
        <site name="MF_m5t.1_l_MF_m5t.1_l-P2" pos="-0.03551 0.016863 -0.00293"/>
        <site name="MF_m5t.2_l_MF_m5t.2_l-P2" pos="-0.0345516 0.0159287 -0.00293"/>
        <site name="MF_m5t.3_l_MF_m5t.3_l-P2" pos="-0.0328228 0.015247 -0.00277"/>
        <site name="MF_m3.laminar_l_MF_m3.laminar_l-P1" pos="-0.0187003 0.0374421 -0.01617"/>
        <site name="MF_m5.laminar_l_MF_m5.laminar_l-P2" pos="-0.0258996 0.01705 -0.00564"/>
        <body name="Abdomen" pos="0.098 0.0711 0">
          <inertial pos="0 0 0" mass="0.01" diaginertia="0.001 0.001 0.001"/>
          <joint name="Abs_t1" pos="0 0 0" axis="1 0 0" limited="true" type="slide" range="-.05 .015"/>
          <joint name="Abs_t2" pos="0 0 0" axis="0 1 0" limited="true" type="slide" range="-.03 .03"/>
          <joint name="Abs_r3" pos="0 0 0" axis="0 0 1" limited="true" range="-.7 .7"/>
          <site name="Abdomen_sidesite" pos="0.011 0 0" class="sidesite"/>
          <site name="EO1_r_EO1_r-P1" pos="0.0065502 0.0627431 0.0308937"/>
          <site name="EO2_r_EO2_r-P2" pos="0.00723321 0.0329565 0.0364551"/>
          <site name="EO3_r_EO3_r-P2" pos="0.00677141 0.0129967 0.0416346"/>
          <site name="EO4_r_default" pos="0.00695134 -0.00599564 0.0403302"/>
          <site name="IO1_r_IO1_r-P1" pos="0.00306951 -0.0406576 0.0453754"/>
          <site name="IO2_r_IO2_r-P1" pos="0.00068053 -0.0115304 0.0513889"/>
          <site name="IO3_r_IO3_r-P1" pos="0.00338096 0.0293052 0.0418774"/>
          <site name="EO1_l_EO1_l-P1" pos="0.0065502 0.0627431 -0.03089"/>
          <site name="EO2_l_EO2_l-P2" pos="0.00723321 0.0329565 -0.03646"/>
          <site name="EO3_l_EO3_l-P2" pos="0.00677141 0.0129967 -0.04163"/>
          <site name="EO4_l_EO4_l-P2" pos="0.00695134 -0.00599564 -0.04033"/>
          <site name="IO1_l_IO1_l-P1" pos="0.00306951 -0.0406576 -0.04538"/>
          <site name="IO2_l_IO2_l-P1" pos="0.00068053 -0.0115304 -0.05139"/>
          <site name="IO3_l_IO3_l-P1" pos="0.00338096 0.0293052 -0.04188"/>
        </body>
        <body name="lumbar4" pos="-0.00 0.0301 0" euler="0 0 0.2">
          <inertial pos="0.0170296 0.018 0" quat="0.707107 0 0 0.707107" mass="1.799" diaginertia="0.01643 0.01123 0.0052"/>
          <joint name="L4_L5_FE" pos="0 0 0" axis="0 0 1" limited="true" range="-0.18607 0.083953"/>
          <joint name="L4_L5_LB" pos="0 0 0" axis="1 0 0" limited="true" range="-0.0889703 0.089703"/>
          <joint name="L4_L5_AR" pos="0 0 0" axis="0 1 0" limited="true" range="-0.3168812 0.3168812"/>
          <geom name="lumbar4_geom_1" type="mesh"  mesh="lumbar4_geom_1_lumbar4"/>
          <site name="Ps_L4_TP_r_Ps_L4_TP_r-P1" pos="-0.015649 0.0249464 0.0258768"/>
          <site name="Ps_L4_L5_IVD_r_Ps_L4_L5_IVD_r-P1" pos="0.00541963 0.00394754 0.0205966"/>
          <site name="Ps_L4_TP_l_Ps_L4_TP_l-P1" pos="-0.015649 0.0249464 -0.02588"/>
          <site name="Ps_L4_L5_IVD_l_Ps_L4_L5_IVD_l-P1" pos="0.00541963 0.00394754 -0.0206"/>
          <site name="IL_L4_r_IL_L4_r-P2" pos="-0.021962 0.0255823 0.0314287"/>
          <site name="IL_L4_l_IL_L4_l-P2" pos="-0.021962 0.0255823 -0.0314287"/>
          <site name="LTpT_T4_r_LTpT_t4_R-P1" pos="-0.0457852 0.00705986 0.00282"/>
          <site name="LTpT_T5_r_LTpT_t5_R-P1" pos="-0.0473001 0.00396965 8e-05"/>
          <site name="LTpT_T8_r_LTpT_t8_R-P2" pos="-0.0469739 0.0180443 0.00565735"/>
          <site name="LTpT_T9_r_LTpT_t9_R-P2" pos="-0.04672 0.01796 0.00748"/>
          <site name="LTpT_T10_r_LTpT_t10_R-P2" pos="-0.04672 0.01796 0.01256"/>
          <site name="LTpT_T11_r_LTpT_t11_R-P2" pos="-0.04672 0.017 0.02194"/>
          <site name="LTpT_T12_r_LTpT_t12_R-P2" pos="-0.04672 0.017 0.02524"/>
          <site name="LTpT_R4_r_LTpT_r4_R-P1" pos="-0.0457852 0.00705986 0.00282013"/>
          <site name="LTpT_R5_r_LTpT_r5_R-P1" pos="-0.0473001 0.00396965 8e-05"/>
          <site name="LTpT_R7_r_LTpT_r7_R-P2" pos="-0.0467202 0.0188294 0.00812957"/>
          <site name="LTpT_R8_r_LTpT_r8_R-P2" pos="-0.0465288 0.0181236 0.0113934"/>
          <site name="LTpT_R9_r_LTpT_r9_R-P2" pos="-0.0467202 0.0176814 0.0148901"/>
          <site name="LTpT_R10_r_LTpT_r10_R-P2" pos="-0.0466654 0.0168641 0.0194391"/>
          <site name="LTpT_R11_r_LTpT_r11_R-P2" pos="-0.0461 0.01796 0.0294188"/>
          <site name="LTpT_R12_r_LTpT_r12_R-P2" pos="-0.04672 0.0175766 0.0335072"/>
          <site name="LTpT_T4_l_LTpT_t4_R-P1" pos="-0.0457852 0.00705986 -0.00282"/>
          <site name="LTpT_T5_l_LTpT_t5_R-P1" pos="-0.0473001 0.00396965 -8e-05"/>
          <site name="LTpT_T8_l_LTpT_t8_R-P2" pos="-0.0469739 0.0180443 -0.00566"/>
          <site name="LTpT_T9_l_LTpT_t9_R-P2" pos="-0.04672 0.01796 -0.00748"/>
          <site name="LTpT_T10_l_LTpT_t10_R-P2" pos="-0.04672 0.01796 -0.01256"/>
          <site name="LTpT_T11_l_LTpT_t11_R-P2" pos="-0.04672 0.017 -0.02194"/>
          <site name="LTpT_T12_l_LTpT_t12_R-P2" pos="-0.04672 0.017 0.02524"/>
          <site name="LTpT_R4_l_LTpT_r4_R-P1" pos="-0.0457852 0.00705986 -0.00282"/>
          <site name="LTpT_R5_l_LTpT_r5_R-P1" pos="-0.0473001 0.00396965 -8e-05"/>
          <site name="LTpT_R7_l_LTpT_r7_R-P2" pos="-0.0467202 0.0188294 -0.00813"/>
          <site name="LTpT_R8_l_LTpT_r8_R-P2" pos="-0.0465288 0.0181236 -0.01139"/>
          <site name="LTpT_R9_l_LTpT_r9_R-P2" pos="-0.0467202 0.0176814 -0.01489"/>
          <site name="LTpT_R10_l_LTpT_r10_R-P2" pos="-0.0466654 0.0168641 -0.01944"/>
          <site name="LTpT_R11_l_LTpT_r11_R-P2" pos="-0.0461 0.01796 -0.02942"/>
          <site name="LTpT_R12_l_LTpT_r12_R-P2" pos="-0.04672 0.0175766 -0.03351"/>
          <site name="LTpL_L4_r_pathpoint_0" pos="-0.0203429 0.0230538 0.0224016"/>
          <site name="LTpL_L4_l_pathpoint_0" pos="-0.0203429 0.0230538 -0.0224"/>
          <site name="QL_post_I.2-L4_r_L4_TP_r-P2" pos="-0.022 0.02605 0.0303"/>
          <site name="QL_post_I.2-L4_l_L4_TP_l-P2" pos="-0.022 0.02605 -0.0303"/>
          <site name="QL_mid_L4-12.3_r_quadratus_lumb_mid_L4_1_r-P2" pos="-0.0213825 0.0307 0.02806"/>
          <site name="QL_mid_L4-12.3_l_quadratus_lumb_mid_L4_1_r-P2" pos="-0.0213825 0.0307 -0.02806"/>
          <site name="MF_m1s_r_MF_m1s_r-P1" pos="-0.0309775 0.0323951 0.0174744"/>
          <site name="MF_m4s_r_MF_m4s_r-P2" pos="-0.0353819 -0.00021522 0.00224284"/>
          <site name="MF_m4t.1_r_MF_m4t.1_r-P2" pos="-0.0418025 0.00016821 0.00288018"/>
          <site name="MF_m4t.2_r_MF_m4t.2_r-P2" pos="-0.0428 0.00017 0.00288"/>
          <site name="MF_m4t.3_r_MF_m4t.3_r-P2" pos="-0.0441 0.00017 0.00288"/>
          <site name="MF_m2.laminar_r_MF_m2.laminar_r-P1" pos="-0.0305622 0.0335037 0.01694"/>
          <site name="MF_m4.laminar_r_MF_m4.laminar_r-P2" pos="-0.0321153 0.00581344 0.00694"/>
          <site name="MF_m1s_l_MF_m1s_l-P1" pos="-0.0309775 0.0323951 -0.01747"/>
          <site name="MF_m4s_l_MF_m4s_l-P2" pos="-0.0353819 -0.00021522 -0.00266"/>
          <site name="MF_m4t.1_l_MF_m4t.1_l-P2" pos="-0.0418025 0.00016821 -0.00224"/>
          <site name="MF_m4t.2_l_MF_m4t.2_l-P2" pos="-0.0428 0.00017 -0.00288"/>
          <site name="MF_m4t.3_l_MF_m4t.3_l-P2" pos="-0.0441 0.00017 -0.00288"/>
          <site name="MF_m2.laminar_l_MF_m2.laminar_l-P1" pos="-0.0305622 0.0335037 -0.01694"/>
          <site name="MF_m4.laminar_l_MF_m4.laminar_l-P2" pos="-0.0321153 0.00581344 -0.00694"/>
          <body name="lumbar3" pos="0.0006 0.0312 0" euler="0 0 0.2">
            <inertial pos="0.0136848 0.018 0" quat="0.707107 0 0 0.707107" mass="1.67" diaginertia="0.01608 0.01066 0.00551"/>
            <joint name="L3_L4_FE" pos="0 0 0" axis="0 0 1" limited="true" range="-0.249288 0.0925752"/>
            <joint name="L3_L4_LB" pos="0 0 0" axis="1 0 0" limited="true" range="-0.1568935 0.1568935"/>
            <joint name="L3_L4_AR" pos="0 0 0" axis="0 1 0" limited="true" range="-0.02968812 0.02968812"/>
            <geom name="lumbar3_geom_1" type="mesh"  mesh="lumbar3_geom_1_lumbar3"/>
            <site name="Ps_L3_TP_r_Ps_L3_TP_r-P1" pos="-0.0245065 0.0207283 0.0282599"/>
            <site name="Ps_L3_L4_IVD_r_Ps_L3_L4_IVD_r-P1" pos="0.00115193 0.00621063 0.0211533"/>
            <site name="Ps_L3_TP_l_Ps_L3_TP_l-P1" pos="-0.0245065 0.0207283 -0.02826"/>
            <site name="Ps_L3_L4_IVD_l_Ps_L3_L4_IVD_l-P1" pos="0.00115193 0.00621063 -0.02115"/>
            <site name="IL_L3_r_IL_L3_r-P2" pos="-0.029216 0.0199881 0.0305391"/>
            <site name="IL_L3_l_IL_L3_l-P2" pos="-0.029216 0.0199881 -0.0305391"/>
            <site name="LTpT_T3_r_LTpT_t3_R-P1" pos="-0.0462017 -0.00342738 0.00407"/>
            <site name="LTpT_T8_r_LTpT_t8_R-P3" pos="-0.0467497 0.0135459 0.00831636"/>
            <site name="LTpT_T9_r_LTpT_t9_R-P3" pos="-0.0464295 0.0138534 0.00968998"/>
            <site name="LTpT_T10_r_LTpT_t10_R-P2_0" pos="-0.0461 0.01403 0.01441"/>
            <site name="LTpT_T11_r_LTpT_t11_R-P3" pos="-0.0501482 0.0134888 0.020885"/>
            <site name="LTpT_T12_r_LTpT_t12_R-P3" pos="-0.0493674 0.0140564 0.0238974"/>
            <site name="LTpT_R6_r_LTpT_r6_R-P2" pos="-0.0469974 0.0147336 0.010844"/>
            <site name="LTpT_R7_r_LTpT_r7_R-P2_0" pos="-0.0461005 0.0141694 0.0128553"/>
            <site name="LTpT_R8_r_LTpT_r8_R-P2_0" pos="-0.0459248 0.0135047 0.0160395"/>
            <site name="LTpT_R9_r_LTpT_r9_R-P2_0" pos="-0.0461005 0.0130235 0.0195821"/>
            <site name="LTpT_R10_r_LTpT_r10_R-P2_0" pos="-0.0460454 0.012674 0.023454"/>
            <site name="LTpT_R11_r_LTpT_r11_R-P3" pos="-0.0461 0.0139338 0.0325773"/>
            <site name="LTpT_R12_r_LTpT_r12_R-P2_0" pos="-0.0461 0.0136439 0.0358736"/>
            <site name="LTpT_T3_l_LTpT_t3_R-P1" pos="-0.0462017 -0.00342738 -0.00407"/>
            <site name="LTpT_T8_l_LTpT_t8_R-P3" pos="-0.0467497 0.0135459 -0.00832"/>
            <site name="LTpT_T9_l_LTpT_t9_R-P3" pos="-0.0464295 0.0138534 -0.00969"/>
            <site name="LTpT_T10_l_LTpT_t10_R-P2_0" pos="-0.0461 0.01403 -0.01441"/>
            <site name="LTpT_T11_l_LTpT_t11_R-P3" pos="-0.0501482 0.0134888 -0.02088"/>
            <site name="LTpT_T12_l_LTpT_t12_R-P3" pos="-0.0493674 0.0140564 0.0238974"/>
            <site name="LTpT_R6_l_LTpT_r6_R-P2" pos="-0.0469974 0.0147336 -0.01084"/>
            <site name="LTpT_R7_l_LTpT_r7_R-P2_0" pos="-0.0461005 0.0141694 -0.01286"/>
            <site name="LTpT_R8_l_LTpT_r8_R-P2_0" pos="-0.0459248 0.0135047 -0.01604"/>
            <site name="LTpT_R9_l_LTpT_r9_R-P2_0" pos="-0.0461005 0.0130235 -0.01958"/>
            <site name="LTpT_R10_l_LTpT_r10_R-P2_0" pos="-0.0460454 0.012674 -0.02345"/>
            <site name="LTpT_R11_l_LTpT_r11_R-P3" pos="-0.0461 0.0139338 -0.03258"/>
            <site name="LTpT_R12_l_LTpT_r12_R-P2_0" pos="-0.0461 0.0136439 -0.03587"/>
            <site name="LTpL_L3_r_pathpoint_0" pos="-0.0291611 0.01963 0.01961"/>
            <site name="LTpL_L3_l_pathpoint_0" pos="-0.0291611 0.01963 -0.01961"/>
            <site name="QL_post_I.1-L3_r_L3_TP_r-P2" pos="-0.029 0.01963 0.0303"/>
            <site name="QL_post_I.2-L3_r_L3_TP_r-P2" pos="-0.029 0.01963 0.0303"/>
            <site name="QL_post_I.3-L3_r_L3_TP_r-P2" pos="-0.029 0.01963 0.0303"/>
            <site name="QL_post_I.1-L3_l_L3_TP_l-P2" pos="-0.029 0.01963 -0.0303"/>
            <site name="QL_post_I.2-L3_l_L3_TP_l-P2" pos="-0.029 0.01963 -0.0303"/>
            <site name="QL_post_I.3-L3_l_L3_TP_l-P2" pos="-0.029 0.01963 -0.0303"/>
            <site name="QL_mid_L3-12.3_r_quadratus_lumb_mid_L3_1_r-P2" pos="-0.0293616 0.0217307 0.03038"/>
            <site name="QL_mid_L3-12.2_r_quadratus_lumb_mid_L3_2_r-P3" pos="-0.02936 0.02173 0.03038"/>
            <site name="QL_mid_L3-12.1_r_quadratus_lumb_mid_L3_3_r-P3" pos="-0.02936 0.02173 0.03038"/>
            <site name="QL_mid_L3-12.3_l_quadratus_lumb_mid_L3_1_r-P2" pos="-0.0293616 0.0217307 -0.03038"/>
            <site name="QL_mid_L3-12.2_l_quadratus_lumb_mid_L3_2_r-P3" pos="-0.02936 0.02173 -0.03038"/>
            <site name="QL_mid_L3-12.1_l_quadratus_lumb_mid_L3_3_r-P3" pos="-0.02936 0.02173 -0.03038"/>
            <site name="MF_m3s_r_MF_m3s_r-P2" pos="-0.0371949 -0.00645328 0.00290733"/>
            <site name="MF_m3t.1_r_MF_m3t.1_r-P2" pos="-0.04338 -0.0102252 0.00166214"/>
            <site name="MF_m3t.2_r_MF_m3t.2_r-P2" pos="-0.04336 -0.01023 0.00266"/>
            <site name="MF_m3t.3_r_MF_m3t.3_r-P2" pos="-0.04336 -0.01023 0.00266"/>
            <site name="MF_m1.laminar_r_MF_m1.laminar_r-P1" pos="-0.0387085 0.02527 0.01691"/>
            <site name="MF_m3.laminar_r_MF_m3.laminar_r-P2" pos="-0.0359442 0.00069045 0.00635"/>
            <site name="MF_m3s_l_MF_m3s_l-P2" pos="-0.0371949 -0.00645328 -0.00237"/>
            <site name="MF_m3t.1_l_MF_m3t.1_l-P2" pos="-0.04338 -0.0102252 -0.00291"/>
            <site name="MF_m3t.2_l_MF_m3t.2_l-P2" pos="-0.04336 -0.01023 -0.00266"/>
            <site name="MF_m3t.3_l_MF_m3t.3_l-P2" pos="-0.04336 -0.01023 -0.00266"/>
            <site name="MF_m1.laminar_l_MF_m1.laminar_l-P1" pos="-0.0387085 0.02527 -0.01691"/>
            <site name="MF_m3.laminar_l_MF_m3.laminar_l-P2" pos="-0.0359442 0.00069045 -0.00635"/>
            <body name="lumbar2" pos="-0.0047 0.0331 0">
              <inertial pos="0.0245272 0.018 0" quat="0.707107 0 0 0.707107" mass="1.689" diaginertia="0.01682 0.01091 0.00591"/>
              <joint name="L2_L3_FE" pos="0 0 0" axis="0 0 1" limited="true" range="-0.282282 0.1048278"/>
              <joint name="L2_L3_LB" pos="0 0 0" axis="1 0 0" limited="true" range="-0.159075 0.159075"/>
              <joint name="L2_L3_AR" pos="0 0 0" axis="0 1 0" limited="true" range="-0.10442594 0.10442594"/>
              <geom name="lumbar2_geom_1" type="mesh"  mesh="lumbar2_geom_1_lumbar2"/>
              <site name="Ps_L2_TP_r_Ps_L2_TP_r-P1" pos="-0.0216214 0.014587 0.022249"/>
              <site name="Ps_L2_L3_IVD_r_Ps_L2_L3_IVD_r-P1" pos="0.00196252 0.00338519 0.0214479"/>
              <site name="Ps_L2_TP_l_Ps_L2_TP_l-P1" pos="-0.0216214 0.014587 -0.02225"/>
              <site name="Ps_L2_L3_IVD_l_Ps_L2_L3_IVD_l-P1" pos="0.00196252 0.00338519 -0.02145"/>
              <site name="IL_L2_r_IL_L2_r-P2" pos="-0.0298319 0.0116685 0.0285294"/>
              <site name="IL_L2_l_IL_L2_l-P2" pos="-0.0298319 0.0116685 -0.0285294"/>
              <site name="IL_R5_r_IL_r5_R-P2" pos="-0.0496298 0.00211134 0.04157"/>
              <site name="IL_R6_r_IL_r6_R-P2" pos="-0.0492143 0.00236612 0.04436"/>
              <site name="IL_R7_r_IL_r7_R-P2" pos="-0.0486649 0.00237387 0.04726"/>
              <site name="IL_R8_r_IL_r8_R-P2" pos="-0.0481978 0.00285524 0.05001"/>
              <site name="IL_R9_r_IL_r9_R-P2" pos="-0.0483524 0.00265461 0.05219"/>
              <site name="IL_R10_r_IL_r10_R-P2" pos="-0.0480883 0.00262684 0.05467"/>
              <site name="IL_R11_r_IL_r11_R-P2" pos="-0.0479471 0.00270337 0.05769"/>
              <site name="IL_R5_l_IL_r5_R-P2" pos="-0.0496298 0.00211134 -0.04157"/>
              <site name="IL_R6_l_IL_r6_R-P2" pos="-0.0492143 0.00236612 -0.04436"/>
              <site name="IL_R7_l_IL_r7_R-P2" pos="-0.0486649 0.00237387 -0.04726"/>
              <site name="IL_R8_l_IL_r8_R-P2" pos="-0.0481978 0.00285524 -0.05001"/>
              <site name="IL_R9_l_IL_r9_R-P2" pos="-0.0483524 0.00265461 -0.05219"/>
              <site name="IL_R10_l_IL_r10_R-P2" pos="-0.0480883 0.00262684 -0.05467"/>
              <site name="IL_R11_l_IL_r11_R-P2" pos="-0.0479471 0.00270337 -0.05769"/>
              <site name="LTpT_T2_r_LTpT_t2_R-P1" pos="-0.0447961 -0.0143228 0.00383"/>
              <site name="LTpT_T5_r_LTpT_t5_R-P2" pos="-0.044 0.0044 0.0064"/>
              <site name="LTpT_T6_r_LTpT_t6_R-P2" pos="-0.044 0.0044 0.009"/>
              <site name="LTpT_T7_r_LTpT_t7_R-P2" pos="-0.04399 0.0044 0.011"/>
              <site name="LTpT_T8_r_LTpT_t8_R-P2_0" pos="-0.0453159 0.00310151 0.01094"/>
              <site name="LTpT_T9_r_LTpT_t9_R-P3_0" pos="-0.0447163 0.00347304 0.0115"/>
              <site name="LTpT_T10_r_LTpT_t10_R-P3" pos="-0.044 0.00338 0.01525"/>
              <site name="LTpT_T11_r_LTpT_t11_R-P2_0" pos="-0.046 0.00338 0.01983"/>
              <site name="LTpT_T12_r_LTpT_t12_R-P2_0" pos="-0.0458028 0.00398333 0.0225543"/>
              <site name="LTpT_R4_r_LTpT_r4_R-P2" pos="-0.0463322 0.00545622 0.0114779"/>
              <site name="LTpT_R5_r_LTpT_r5_R-P2" pos="-0.0474338 0.00463268 0.0141962"/>
              <site name="LTpT_R6_r_LTpT_r6_R-P2_0" pos="-0.044 0.0044 0.014"/>
              <site name="LTpT_R7_r_LTpT_r7_R-P2_1" pos="-0.04399 0.00431532 0.0172724"/>
              <site name="LTpT_R8_r_LTpT_r8_R-P2_1" pos="-0.04399 0.00388 0.0205414"/>
              <site name="LTpT_R9_r_LTpT_r9_R-P2_1" pos="-0.0439905 0.00393671 0.0241884"/>
              <site name="LTpT_R10_r_LTpT_r10_R-P2_1" pos="-0.0439356 0.00364643 0.027333"/>
              <site name="LTpT_R11_r_LTpT_r11_R-P4" pos="-0.0440238 0.00448 0.0355734"/>
              <site name="LTpT_R12_r_LTpT_r12_R-P2_1" pos="-0.044 0.0044 0.0388153"/>
              <site name="LTpT_T2_l_LTpT_t2_R-P1" pos="-0.0447961 -0.0143228 -0.00383"/>
              <site name="LTpT_T5_l_LTpT_t5_R-P2" pos="-0.044 0.0044 -0.0064"/>
              <site name="LTpT_T6_l_LTpT_t6_R-P2" pos="-0.044 0.0044 -0.009"/>
              <site name="LTpT_T7_l_LTpT_t7_R-P2" pos="-0.04399 0.0044 -0.011"/>
              <site name="LTpT_T8_l_LTpT_t8_R-P2_0" pos="-0.0453159 0.00310151 -0.01094"/>
              <site name="LTpT_T9_l_LTpT_t9_R-P3_0" pos="-0.0447163 0.00347304 -0.0115"/>
              <site name="LTpT_T10_l_LTpT_t10_R-P3" pos="-0.044 0.00338 -0.01525"/>
              <site name="LTpT_T11_l_LTpT_t11_R-P2_0" pos="-0.046 0.00338 -0.01983"/>
              <site name="LTpT_T12_l_LTpT_t12_R-P2_0" pos="-0.0458028 0.00398333 0.0225543"/>
              <site name="LTpT_R4_l_LTpT_r4_R-P2" pos="-0.0463322 0.00545622 -0.01148"/>
              <site name="LTpT_R5_l_LTpT_r5_R-P2" pos="-0.0474338 0.00463268 -0.0142"/>
              <site name="LTpT_R6_l_LTpT_r6_R-P2_0" pos="-0.044 0.0044 -0.014"/>
              <site name="LTpT_R7_l_LTpT_r7_R-P2_1" pos="-0.04399 0.00431532 -0.01727"/>
              <site name="LTpT_R8_l_LTpT_r8_R-P2_1" pos="-0.04399 0.00388 -0.02054"/>
              <site name="LTpT_R9_l_LTpT_r9_R-P2_1" pos="-0.0439905 0.00393671 -0.02419"/>
              <site name="LTpT_R10_l_LTpT_r10_R-P2_1" pos="-0.0439356 0.00364643 -0.02733"/>
              <site name="LTpT_R11_l_LTpT_r11_R-P4" pos="-0.0440238 0.00448 -0.03557"/>
              <site name="LTpT_R12_l_LTpT_r12_R-P2_1" pos="-0.044 0.0044 -0.03882"/>
              <site name="LTpL_L2_r_pathpoint_0" pos="-0.0287627 0.0125583 0.0202959"/>
              <site name="LTpL_L2_l_pathpoint_0" pos="-0.02876 0.0125583 -0.0203"/>
              <site name="QL_post_I.2-L2_r_L2_TP_r-P2" pos="-0.031 0.012 0.0303"/>
              <site name="QL_post_I.3-L2_r_L2_TP_r-P2" pos="-0.031 0.012 0.0303"/>
              <site name="QL_post_I.2-L2_l_L2_TP_l-P2" pos="-0.031 0.012 -0.0303"/>
              <site name="QL_post_I.3-L2_l_L2_TP_l-P2" pos="-0.031 0.012 -0.0303"/>
              <site name="QL_mid_L2-12.1_r_QL_mid_L2-12.1_l-P1_0" pos="-0.0291214 0.0168959 0.02562"/>
              <site name="QL_mid_L2-12.1_l_QL_mid_L2-12.1_l-P1_0" pos="-0.0291214 0.0168959 -0.02562"/>
              <site name="MF_m2s_r_MF_m2s_r-P2" pos="-0.0358341 -0.0117591 0.00354943"/>
              <site name="MF_m2t.1_r_MF_m2t.1_r-P2" pos="-0.03956 -0.01839 0.00364"/>
              <site name="MF_m2t.2_r_MF_m2t.2_r-P2" pos="-0.03956 -0.01839 0.00364"/>
              <site name="MF_m2t.3_r_MF_m2t.3_r-P2" pos="-0.038808 -0.0187383 0.00236534"/>
              <site name="MF_m2.laminar_r_MF_m2.laminar_r-P2" pos="-0.032901 -0.00561 0.00674"/>
              <site name="MF_m2s_l_MF_m2s_l-P2" pos="-0.0358341 -0.0117591 -0.00355"/>
              <site name="MF_m2t.1_l_MF_m2t.1_l-P2" pos="-0.03956 -0.01839 -0.00364"/>
              <site name="MF_m2t.2_l_MF_m2t.2_l-P2" pos="-0.03956 -0.01839 -0.00364"/>
              <site name="MF_m2t.3_l_MF_m2t.3_l-P2" pos="-0.038808 -0.0187383 -0.00364"/>
              <site name="MF_m2.laminar_l_MF_m2.laminar_l-P2" pos="-0.032901 -0.00561 -0.00674"/>
              <body name="lumbar1" pos="-0.0044 0.0288 0" euler="0 0 0.2">
                <inertial pos="0.039 0.017 0" quat="0.707107 0 0 0.707107" mass="1.677" diaginertia="0.01753 0.01113 0.0064"/>
                <joint name="L1_L2_FE" pos="0 0 0" axis="0 0 1" limited="true" range="-0.31161 0.115719"/>
                <joint name="L1_L2_LB" pos="0 0 0" axis="1 0 0" limited="true" range="-0.0820244 0.0820244"/>
                <joint name="L1_L2_AR" pos="0 0 0" axis="0 1 0" limited="true" range="-0.08269806 0.08269806"/>
                <geom name="lumbar1_geom_1" type="mesh"  mesh="lumbar1_geom_1_lumbar1"/>
                <site name="Ps_L1_VB_r_Ps_L1_VB_r-P1" pos="-0.0101595 0.02327 0.02"/>
                <site name="Ps_L1_TP_r_Ps_L1_TP_r-P1" pos="-0.02325 0.0146584 0.0226252"/>
                <site name="Ps_L1_L2_IVD_r_Ps_L1_L2_IVD_r-P1" pos="-0.00125362 0.00350798 0.0206834"/>
                <site name="Ps_L1_VB_l_Ps_L1_VB_l-P1" pos="-0.0101595 0.02327 -0.02"/>
                <site name="Ps_L1_TP_l_Ps_L1_TP_l-P1" pos="-0.02325 0.0146584 -0.02263"/>
                <site name="Ps_L1_L2_IVD_l_Ps_L1_L2_IVD_l-P1" pos="-0.00125362 0.00350798 -0.02068"/>
                <site name="IL_L1_r_IL_L1_r-P2" pos="-0.0300702 0.0155021 0.0291785"/>
                <site name="IL_L1_l_IL_L1_l-P2" pos="-0.0300702 0.0155021 -0.0291785"/>
                <site name="LTpT_T1_r_LTpT_t1_R-P1" pos="-0.0459749 -0.0105702 0.00321"/>
                <site name="LTpT_T3_r_LTpT_t3_R-P2" pos="-0.03711 -0.01402 0.005"/>
                <site name="LTpT_T4_r_LTpT_t4_R-P2" pos="-0.0371129 -0.0140247 0.00612"/>
                <site name="LTpT_T1_l_LTpT_t1_R-P1" pos="-0.0459749 -0.0105702 -0.00321"/>
                <site name="LTpT_T3_l_LTpT_t3_R-P2" pos="-0.03711 -0.01402 -0.005"/>
                <site name="LTpT_T4_l_LTpT_t4_R-P2" pos="-0.0371129 -0.0140247 -0.00612"/>
                <site name="LTpL_L1_r_pathpoint_0" pos="-0.0290759 0.0150555 0.0217951"/>
                <site name="LTpL_L1_l_pathpoint_0" pos="-0.0290759 0.0150555 -0.0218"/>
                <site name="QL_post_I.3-L1_r_L1_TP-P1" pos="-0.0326362 0.0148767 0.029"/>
                <site name="QL_post_I.3-L1_l_L1_TP_l-P1" pos="-0.0326362 0.0148767 -0.029"/>
                <site name="MF_m1s_r_MF_m1s_r-P2" pos="-0.0343145 -0.0131463 0.00301684"/>
                <site name="MF_m1t.1_r_MF_m1t.1_r-P2" pos="-0.0409385 -0.0160046 0.00309636"/>
                <site name="MF_m1t.2_r_MF_m1t.2_r-P2" pos="-0.04094 -0.016 0.0031"/>
                <site name="MF_m1t.3_r_MF_m1t.3_r-P2" pos="-0.04094 -0.016 0.0031"/>
                <site name="MF_m1.laminar_r_MF_m1.laminar_r-P2" pos="-0.0341019 -0.00560525 0.00619"/>
                <site name="MF_m1s_l_MF_m1s_l-P2" pos="-0.0343145 -0.0131463 -0.00302"/>
                <site name="MF_m1t.1_l_MF_m1t.1_l-P2" pos="-0.0409385 -0.0160046 -0.0031"/>
                <site name="MF_m1t.2_l_MF_m1t.2_l-P2" pos="-0.04094 -0.016 -0.0031"/>
                <site name="MF_m1t.3_l_MF_m1t.3_l-P2" pos="-0.04094 -0.016 -0.0031"/>
                <site name="MF_m1.laminar_l_MF_m1.laminar_l-P2" pos="-0.0341019 -0.00560525 -0.00619"/>
                <body name="torso" pos="-0.018 -0.085 0" euler="0 0 -0.33">
                  <inertial pos="0.0046 0.246 0" mass="18.619" diaginertia="0.165 0.15 0.125"/>
				          <body name="head_attach" pos="-0.005 -0.01 0">
					          <site name="head" pos="0 0.65 0" group="4" class="myo_leg_marker"/>
                    <include file="../../../../simhive/myo_sim/head/assets/myohead_rigid_chain.xml"/>
                  </body>
                  <geom name="torso_geom_1" pos="-0.019 0.121 0" quat="0.980067 0 0 0.198669" type="mesh"  mesh="torso_geom_1_thoracic12_s"/>
                  <geom name="torso_geom_2" pos="-0.032 0.146 0" quat="0.995004 0 0 0.0998334" type="mesh"  mesh="torso_geom_2_thoracic11_s"/>
                  <geom name="torso_geom_3" pos="-0.04 0.171 0" quat="0.997189 0 0 0.0749297" type="mesh"  mesh="torso_geom_3_thoracic10_s"/>
                  <geom name="torso_geom_4" pos="-0.043 0.198 0" quat="0.99875 0 0 0.0499792" type="mesh"  mesh="torso_geom_4_thoracic9_s"/>
                  <geom name="torso_geom_5" pos="-0.045 0.223 0" quat="0.9998 0 0 -0.0199987" type="mesh"  mesh="torso_geom_5_thoracic8_s"/>
                  <geom name="torso_geom_6" pos="-0.044 0.249 0" quat="0.99955 0 0 -0.0299955" type="mesh"  mesh="torso_geom_6_thoracic7_s"/>
                  <geom name="torso_geom_7" pos="-0.043 0.27 0" quat="0.99955 0 0 -0.0299955" type="mesh"  mesh="torso_geom_7_thoracic6_s"/>
                  <geom name="torso_geom_8" pos="-0.041 0.292 0" quat="0.99875 0 0 -0.0499792" type="mesh"  mesh="torso_geom_8_thoracic5_s"/>
                  <geom name="torso_geom_9" pos="-0.0395 0.314 0" quat="0.997189 0 0 -0.0749297" type="mesh"  mesh="torso_geom_9_thoracic4_s"/>
                  <geom name="torso_geom_10" pos="-0.036 0.337 0" quat="0.995004 0 0 -0.0998334" type="mesh"  mesh="torso_geom_10_thoracic3_s"/>
                  <geom name="torso_geom_11" pos="-0.032 0.358 0" quat="0.992198 0 0 -0.124675" type="mesh"  mesh="torso_geom_11_thoracic2_s"/>
                  <geom name="torso_geom_12" pos="-0.028 0.375 0" quat="0.988771 0 0 -0.149438" type="mesh"  mesh="torso_geom_12_thoracic1_s"/>
                  <geom name="torso_geom_13" pos="0.028 0.365 0" type="mesh"  mesh="torso_geom_13_ribcage_s"/>
                  <geom type="capsule" class="myotorso_coll" size="0.080 0.077" pos=".036 -.020 0" euler="0 0 1.57"/>
                  <geom type="ellipsoid" class="myotorso_coll" size="0.260 0.095 0.140" pos=".016 .160 0" euler="0 0 1.7"/>
                  <geom type="capsule" class="myotorso_coll" size="0.110 0.065" pos=".011 .250 0" euler="0 0 1.57"/>
                  <geom type="capsule" class="myotorso_coll" size="0.075 0.145" pos="-.009 .335 0" euler="0 0 1.57"/>
                  <geom name="back_cylinder_l" size="0.17 0.13" pos="-0.21 0.04 0" class="myoBack_wrap"/>
                  <geom name="Chest_r_ellipsoid" size="0.073" pos="0.008 0.21 0.01" quat="0.97517 -0.0198338 -0.197677 0.0978434" rgba=".5 .5 .9 0.5" group="3" contype="0" conaffinity="0"/>
                  <geom name="Chest_l_ellipsoid" size="0.073" pos="0.008 0.21 -0.01" quat="0.97517 0.0198338 0.197677 0.0978434" rgba=".5 .5 .9 0.5" group="3" contype="0" conaffinity="0"/>
                  <geom name="Cylinder_abdomen" size="0.09 0.13" pos="0.225 0.10 0" class="myoBack_wrap"/>
                  <site name="Abs_sidesite" pos="0.03 0.05 0" class="sidesite" />
                  <site name="LeftShoulder" pos="-0.11 0.3 -0.07" size="0.0005" rgba="0 1 0 1"/>
                  <site name="RightShoulder" pos="-0.11 0.3 0.07" size="0.0005" rgba="0 1 0 1"/>
                  <site name="Chest_r_sidesite" pos="-0.02082 0.21 0.07816" class="sidesite"/>
                  <site name="Chest_l_sidesite" pos="-0.02082 0.21 -0.07816" class="sidesite"/>
                  <site name="rect_abd_r_rect_abd_r-P2" pos="0.0880597 0.222575 -0.0344509"/>
                  <site name="rect_abd_l_rect_abd_l-P2" pos="0.08806 0.22257 0.03445"/>
                  <site name="back_cylinder_l_IL_L2_r_1_sidesite" pos="-0.0673295 -0.0432604 -0.020523" class="sidesite"/>
                  <site name="back_cylinder_l_IL_L3_r_1_sidesite" pos="-0.108976 0.217229 0.0537206" class="sidesite"/>
                  <site name="back_cylinder_l_IL_L4_r_1_sidesite" pos="-0.0465512 0.162068 -0.10054" class="sidesite"/>
                  <site name="back_cylinder_l_IL_L2_l_1_sidesite" pos="-0.067766 -0.047199 -0.020314" class="sidesite"/>
                  <site name="back_cylinder_l_IL_L3_l_1_sidesite" pos="-0.00732879 0.0167539 0.0354792" class="sidesite"/>
                  <site name="back_cylinder_l_IL_L4_l_1_sidesite" pos="-0.00798834 0.0115872 -0.107672" class="sidesite"/>
                  <site name="IL_R5_r_IL_r5_R-P2_0" pos="-0.07928 0.175415 0.0432678"/>
                  <site name="IL_R5_r_IL_r5_R-P3" pos="-0.0807876 0.202609 0.0433988"/>
                  <site name="IL_R5_r_IL_r5_R-P4" pos="-0.082702 0.23174 0.0437724"/>
                  <site name="IL_R5_r_IL_r5_R-P5" pos="-0.0835858 0.260188 0.0450128"/>
                  <site name="IL_R5_r_IL_r5_R-P6" pos="-0.0808487 0.280829 0.0453018"/>
                  <site name="IL_R5_r_IL_r5_R-P7" pos="-0.0761377 0.300764 0.0455678"/>
                  <site name="IL_R6_r_IL_r6_R-P2_0" pos="-0.0800841 0.173627 0.0461472"/>
                  <site name="IL_R6_r_IL_r6_R-P3" pos="-0.083302 0.205151 0.046425"/>
                  <site name="IL_R6_r_IL_r6_R-P4" pos="-0.0839592 0.235088 0.04728"/>
                  <site name="IL_R6_r_IL_r6_R-P5" pos="-0.0816046 0.262818 0.0482667"/>
                  <site name="IL_R6_r_IL_r6_R-P6" pos="-0.0762123 0.276765 0.0485857"/>
                  <site name="IL_R7_r_IL_r7_R-P2_0" pos="-0.0803486 0.174563 0.0486571"/>
                  <site name="IL_R7_r_IL_r7_R-P3" pos="-0.0833554 0.203554 0.0491766"/>
                  <site name="IL_R7_r_IL_r7_R-P4" pos="-0.084366 0.234157 0.0495515"/>
                  <site name="IL_R7_r_IL_r7_R-P5" pos="-0.0792041 0.257745 0.0508997"/>
                  <site name="IL_R8_r_IL_r8_R-P2_0" pos="-0.0790523 0.170344 0.0512329"/>
                  <site name="IL_R8_r_IL_r8_R-P3" pos="-0.0811061 0.203526 0.0510496"/>
                  <site name="IL_R8_r_IL_r8_R-P4" pos="-0.079718 0.227964 0.0522864"/>
                  <site name="IL_R9_r_IL_r9_R-P2_0" pos="-0.0794897 0.174496 0.05371"/>
                  <site name="IL_R9_r_IL_r9_R-P3" pos="-0.07694 0.193965 0.0537859"/>
                  <site name="IL_R10_r_IL_r10_R-P2_0" pos="-0.0749575 0.162842 0.0562343"/>
                  <site name="IL_R11_r_IL_r11_R-P2_0" pos="-0.0624397 0.135882 0.0599046"/>
                  <site name="IL_R12_r_IL_r12_R-P2" pos="-0.0383346 0.106097 0.0593963"/>
                  <site name="IL_R5_l_IL_r5_R-P2_0" pos="-0.07928 0.175415 -0.04327"/>
                  <site name="IL_R5_l_IL_r5_R-P3" pos="-0.0807876 0.202609 -0.0434"/>
                  <site name="IL_R5_l_IL_r5_R-P4" pos="-0.082702 0.23174 -0.04377"/>
                  <site name="IL_R5_l_IL_r5_R-P5" pos="-0.0835858 0.260188 -0.04501"/>
                  <site name="IL_R5_l_IL_r5_R-P6" pos="-0.0808487 0.280829 -0.0453"/>
                  <site name="IL_R5_l_IL_r5_R-P7" pos="-0.0761377 0.300764 -0.04557"/>
                  <site name="IL_R6_l_IL_r6_R-P2_0" pos="-0.0800841 0.173627 -0.04615"/>
                  <site name="IL_R6_l_IL_r6_R-P3" pos="-0.083302 0.205151 -0.04643"/>
                  <site name="IL_R6_l_IL_r6_R-P4" pos="-0.0839592 0.235088 -0.04728"/>
                  <site name="IL_R6_l_IL_r6_R-P5" pos="-0.0816046 0.262818 -0.04827"/>
                  <site name="IL_R6_l_IL_r6_R-P6" pos="-0.0762123 0.276765 -0.04859"/>
                  <site name="IL_R7_l_IL_r7_R-P2_0" pos="-0.0803486 0.174563 -0.04866"/>
                  <site name="IL_R7_l_IL_r7_R-P3" pos="-0.0833554 0.203554 -0.04918"/>
                  <site name="IL_R7_l_IL_r7_R-P4" pos="-0.084366 0.234157 -0.04955"/>
                  <site name="IL_R7_l_IL_r7_R-P5" pos="-0.0792041 0.257745 -0.0509"/>
                  <site name="IL_R8_l_IL_r8_R-P2_0" pos="-0.0790523 0.170344 -0.05123"/>
                  <site name="IL_R8_l_IL_r8_R-P3" pos="-0.0811061 0.203526 -0.05105"/>
                  <site name="IL_R8_l_IL_r8_R-P4" pos="-0.079718 0.227964 -0.05229"/>
                  <site name="IL_R9_l_IL_r9_R-P2_0" pos="-0.0794897 0.174496 -0.05371"/>
                  <site name="IL_R9_l_IL_r9_R-P3" pos="-0.07694 0.193965 -0.05379"/>
                  <site name="IL_R10_l_IL_r10_R-P2_0" pos="-0.0749575 0.162842 -0.05623"/>
                  <site name="IL_R11_l_IL_r11_R-P2_0" pos="-0.0624397 0.135882 -0.0599"/>
                  <site name="IL_R12_l_IL_r12_R-P2" pos="-0.0383346 0.106097 -0.0594"/>
                  <site name="LTpT_T1_r_LTpT_t1_R-P2" pos="-0.0523817 0.399196 0.02615"/>
                  <site name="Chest_r_ellipsoid_LTpT_T1_r_1_sidesite" pos="-0.06459 0.2237 0.01425" class="sidesite"/>
                  <site name="LTpT_T2_r_LTpT_t2_R-P2" pos="-0.0561283 0.380255 0.02654"/>
                  <site name="Chest_r_ellipsoid_LTpT_T2_r_1_sidesite" pos="-0.06459 0.2237 0.01425" class="sidesite"/>
                  <site name="LTpT_T3_r_LTpT_t3_R-P2_0" pos="-0.0651001 0.358859 0.02598"/>
                  <site name="Chest_r_ellipsoid_LTpT_T3_r_2_sidesite" pos="-0.06459 0.2237 0.01425" class="sidesite"/>
                  <site name="LTpT_T4_r_LTpT_t4_R-P2_0" pos="-0.0732536 0.337677 0.02615"/>
                  <site name="Chest_r_ellipsoid_LTpT_T4_r_2_sidesite" pos="-0.06459 0.2237 0.01425" class="sidesite"/>
                  <site name="LTpT_T5_r_LTpT_t5_R-P2_0" pos="-0.0761378 0.314622 0.02808"/>
                  <site name="Chest_r_ellipsoid_LTpT_T5_r_2_sidesite" pos="-0.06459 0.2237 0.01425" class="sidesite"/>
                  <site name="LTpT_T6_r_LTpT_t6_R-P3" pos="-0.0747978 0.186286 0.0154652"/>
                  <site name="LTpT_T6_r_LTpT_t6_R-P2_0" pos="-0.08338 0.289296 0.02766"/>
                  <site name="LTpT_T7_r_LTpT_t7_R-P3" pos="-0.0759558 0.18626 0.0195571"/>
                  <site name="LTpT_T7_r_LTpT_t7_R-P2_0" pos="-0.0822431 0.263091 0.02647"/>
                  <site name="LTpT_T8_r_LTpT_t8_R-P2_1" pos="-0.0804592 0.235899 0.0255"/>
                  <site name="LTpT_T9_r_LTpT_t9_R-P2_0" pos="-0.07694 0.218354 0.02633"/>
                  <site name="LTpT_T10_r_LTpT_t10_R-P2_1" pos="-0.0698233 0.189776 0.0181"/>
                  <site name="LTpT_T11_r_LTpT_t11_R-P2_1" pos="-0.060879 0.161718 0.01762"/>
                  <site name="LTpT_T12_r_LTpT_t12_R-P2_1" pos="-0.052717 0.13133 0.01818"/>
                  <site name="LTpT_R4_r_LTpT_r4_R-P2_0" pos="-0.0768261 0.18568 0.0259954"/>
                  <site name="LTpT_R4_r_LTpT_r4_R-P3" pos="-0.0775768 0.21098 0.0285848"/>
                  <site name="LTpT_R4_r_LTpT_r4_R-P4" pos="-0.0782966 0.237256 0.0311206"/>
                  <site name="LTpT_R4_r_LTpT_r4_R-P5" pos="-0.0768087 0.264526 0.0335195"/>
                  <site name="LTpT_R4_r_LTpT_r4_R-P6" pos="-0.0755378 0.329822 0.038393"/>
                  <site name="LTpT_R5_r_LTpT_r5_R-P2_0" pos="-0.0798949 0.184355 0.0299068"/>
                  <site name="LTpT_R5_r_LTpT_r5_R-P3" pos="-0.0792869 0.209431 0.0319682"/>
                  <site name="LTpT_R5_r_LTpT_r5_R-P4" pos="-0.0800066 0.236893 0.0346445"/>
                  <site name="LTpT_R5_r_LTpT_r5_R-P5" pos="-0.0777671 0.26326 0.0365163"/>
                  <site name="LTpT_R5_r_LTpT_r5_R-P6" pos="-0.0748222 0.303827 0.0391932"/>
                  <site name="LTpT_R6_r_LTpT_r6_R-P2_1" pos="-0.0798949 0.182502 0.0310073"/>
                  <site name="LTpT_R6_r_LTpT_r6_R-P3" pos="-0.0803073 0.209123 0.0346608"/>
                  <site name="LTpT_R6_r_LTpT_r6_R-P4" pos="-0.080858 0.236432 0.0373467"/>
                  <site name="LTpT_R6_r_LTpT_r6_R-P5" pos="-0.0774916 0.263171 0.0395202"/>
                  <site name="LTpT_R6_r_LTpT_r6_R-P6" pos="-0.07361 0.282893 0.0400955"/>
                  <site name="LTpT_R7_r_LTpT_r7_R-P2_2" pos="-0.0803487 0.181455 0.0354903"/>
                  <site name="LTpT_R7_r_LTpT_r7_R-P3" pos="-0.0808579 0.207772 0.0395886"/>
                  <site name="LTpT_R7_r_LTpT_r7_R-P4" pos="-0.0818684 0.235973 0.0422488"/>
                  <site name="LTpT_R7_r_LTpT_r7_R-P5" pos="-0.0792041 0.259426 0.0433327"/>
                  <site name="LTpT_R8_r_LTpT_r8_R-P2_2" pos="-0.0812671 0.180838 0.0407129"/>
                  <site name="LTpT_R8_r_LTpT_r8_R-P3" pos="-0.0811062 0.206371 0.0437166"/>
                  <site name="LTpT_R8_r_LTpT_r8_R-P4" pos="-0.079718 0.230529 0.0463537"/>
                  <site name="LTpT_R9_r_LTpT_r9_R-P2_2" pos="-0.0807942 0.178822 0.043359"/>
                  <site name="LTpT_R9_r_LTpT_r9_R-P3" pos="-0.0802242 0.200367 0.0467599"/>
                  <site name="LTpT_R10_r_LTpT_r10_R-P2_2" pos="-0.0791894 0.172879 0.0468867"/>
                  <site name="LTpT_R11_r_LTpT_r11_R-P2_0" pos="-0.0650216 0.147656 0.045555"/>
                  <site name="LTpT_R12_r_LTpT_r12_R-P2_2" pos="-0.0450351 0.121644 0.0466148"/>
                  <site name="LTpT_T1_l_LTpT_t1_R-P2" pos="-0.0523817 0.399196 -0.02615"/>
                  <site name="Chest_l_ellipsoid_LTpT_T1_l_1_sidesite" pos="-0.06459 0.2237 -0.01425" class="sidesite"/>
                  <site name="LTpT_T2_l_LTpT_t2_R-P2" pos="-0.0561283 0.380255 -0.02654"/>
                  <site name="Chest_l_ellipsoid_LTpT_T2_l_1_sidesite" pos="-0.06459 0.2237 -0.01425" class="sidesite"/>
                  <site name="LTpT_T3_l_LTpT_t3_R-P2_0" pos="-0.0651001 0.358859 -0.02598"/>
                  <site name="Chest_l_ellipsoid_LTpT_T3_l_2_sidesite" pos="-0.06459 0.2237 -0.01425" class="sidesite"/>
                  <site name="LTpT_T4_l_LTpT_t4_R-P2_0" pos="-0.0732536 0.337677 -0.02615"/>
                  <site name="Chest_l_ellipsoid_LTpT_T4_l_2_sidesite" pos="-0.06459 0.2237 -0.01425" class="sidesite"/>
                  <site name="LTpT_T5_l_LTpT_t5_R-P2_0" pos="-0.0761378 0.314622 -0.02808"/>
                  <site name="Chest_l_ellipsoid_LTpT_T5_l_2_sidesite" pos="-0.06459 0.2237 -0.01425" class="sidesite"/>
                  <site name="LTpT_T6_l_LTpT_t6_R-P3" pos="-0.0747978 0.186286 -0.01547"/>
                  <site name="LTpT_T6_l_LTpT_t6_R-P2_0" pos="-0.08338 0.289296 -0.02766"/>
                  <site name="LTpT_T7_l_LTpT_t7_R-P3" pos="-0.0759558 0.18626 -0.01956"/>
                  <site name="LTpT_T7_l_LTpT_t7_R-P2_0" pos="-0.0822431 0.263091 -0.02647"/>
                  <site name="LTpT_T8_l_LTpT_t8_R-P2_1" pos="-0.0804592 0.235899 -0.0255"/>
                  <site name="LTpT_T9_l_LTpT_t9_R-P2_0" pos="-0.07694 0.218354 -0.02633"/>
                  <site name="LTpT_T10_l_LTpT_t10_R-P2_1" pos="-0.0698233 0.189776 -0.0181"/>
                  <site name="LTpT_T11_l_LTpT_t11_R-P2_1" pos="-0.060879 0.161718 -0.01762"/>
                  <site name="LTpT_T12_l_LTpT_t12_R-P2_1" pos="-0.052717 0.13133 0.01818"/>
                  <site name="LTpT_R4_l_LTpT_r4_R-P2_0" pos="-0.0768261 0.18568 -0.026"/>
                  <site name="LTpT_R4_l_LTpT_r4_R-P3" pos="-0.0775768 0.21098 -0.02858"/>
                  <site name="LTpT_R4_l_LTpT_r4_R-P4" pos="-0.0782966 0.237256 -0.03112"/>
                  <site name="LTpT_R4_l_LTpT_r4_R-P5" pos="-0.0768087 0.264526 -0.03352"/>
                  <site name="LTpT_R4_l_LTpT_r4_R-P6" pos="-0.0755378 0.329822 -0.03839"/>
                  <site name="LTpT_R5_l_LTpT_r5_R-P2_0" pos="-0.0798949 0.184355 -0.02991"/>
                  <site name="LTpT_R5_l_LTpT_r5_R-P3" pos="-0.0792869 0.209431 -0.03197"/>
                  <site name="LTpT_R5_l_LTpT_r5_R-P4" pos="-0.0800066 0.236893 -0.03464"/>
                  <site name="LTpT_R5_l_LTpT_r5_R-P5" pos="-0.0777671 0.26326 -0.03652"/>
                  <site name="LTpT_R5_l_LTpT_r5_R-P6" pos="-0.0748222 0.303827 -0.03919"/>
                  <site name="LTpT_R6_l_LTpT_r6_R-P2_1" pos="-0.0798949 0.182502 -0.03101"/>
                  <site name="LTpT_R6_l_LTpT_r6_R-P3" pos="-0.0803073 0.209123 -0.03466"/>
                  <site name="LTpT_R6_l_LTpT_r6_R-P4" pos="-0.080858 0.236432 -0.03735"/>
                  <site name="LTpT_R6_l_LTpT_r6_R-P5" pos="-0.0774916 0.263171 -0.03952"/>
                  <site name="LTpT_R6_l_LTpT_r6_R-P6" pos="-0.07361 0.282893 -0.0401"/>
                  <site name="LTpT_R7_l_LTpT_r7_R-P2_2" pos="-0.0803487 0.181455 -0.03549"/>
                  <site name="LTpT_R7_l_LTpT_r7_R-P3" pos="-0.0808579 0.207772 -0.03959"/>
                  <site name="LTpT_R7_l_LTpT_r7_R-P4" pos="-0.0818684 0.235973 -0.04225"/>
                  <site name="LTpT_R7_l_LTpT_r7_R-P5" pos="-0.0792041 0.259426 -0.04333"/>
                  <site name="LTpT_R8_l_LTpT_r8_R-P2_2" pos="-0.0812671 0.180838 -0.04071"/>
                  <site name="LTpT_R8_l_LTpT_r8_R-P3" pos="-0.0811062 0.206371 -0.04372"/>
                  <site name="LTpT_R8_l_LTpT_r8_R-P4" pos="-0.079718 0.230529 -0.04635"/>
                  <site name="LTpT_R9_l_LTpT_r9_R-P2_2" pos="-0.0807942 0.178822 -0.04336"/>
                  <site name="LTpT_R9_l_LTpT_r9_R-P3" pos="-0.0802242 0.200367 -0.04676"/>
                  <site name="LTpT_R10_l_LTpT_r10_R-P2_2" pos="-0.0791894 0.172879 -0.04689"/>
                  <site name="LTpT_R11_l_LTpT_r11_R-P2_0" pos="-0.0650216 0.147656 -0.04556"/>
                  <site name="LTpT_R12_l_LTpT_r12_R-P2_2" pos="-0.0450351 0.121644 -0.04661"/>
                  <site name="QL_mid_L3-12.3_r_quadratus_lumb_mid_L3_1_r-P1" pos="-0.0419115 0.11237 0.05166"/>
                  <site name="QL_mid_L3-12.2_r_quadratus_lumb_mid_L3_2_r-P2" pos="-0.0424782 0.119222 0.04319"/>
                  <site name="QL_mid_L3-12.1_r_quadratus_lumb_mid_L3_3_r-P2" pos="-0.0412845 0.1282 0.03119"/>
                  <site name="QL_mid_L2-12.1_r_QL_mid_L2-12.1_l-P1" pos="-0.04128 0.1282 0.03119"/>
                  <site name="QL_mid_L4-12.3_r_quadratus_lumb_mid_L4_1_r-P1" pos="-0.0417825 0.112316 0.05167"/>
                  <site name="QL_mid_L3-12.3_l_quadratus_lumb_mid_L3_1_r-P1" pos="-0.0419115 0.11237 -0.05166"/>
                  <site name="QL_mid_L3-12.2_l_quadratus_lumb_mid_L3_2_r-P2" pos="-0.0424782 0.119222 -0.04319"/>
                  <site name="QL_mid_L3-12.1_l_quadratus_lumb_mid_L3_3_r-P2" pos="-0.0412845 0.1282 -0.03119"/>
                  <site name="QL_mid_L2-12.1_l_QL_mid_L2-12.1_l-P1" pos="-0.04128 0.1282 -0.03119"/>
                  <site name="QL_mid_L4-12.3_l_quadratus_lumb_mid_L4_1_r-P1" pos="-0.0417825 0.112316 -0.05167"/>
                  <site name="QL_ant_I.2-T12_r_T12_r-P2" pos="-0.0142008 0.13014 0.01737"/>
                  <site name="QL_ant_I.3-T12_r_T12_r-P2" pos="-0.0142008 0.13014 0.01737"/>
                  <site name="QL_ant_I.2-12.1_r_12.1_r-P3" pos="-0.0402807 0.124401 0.03745"/>
                  <site name="QL_ant_I.3-12.1_r_12.1_r-P2" pos="-0.0402807 0.124401 0.03745"/>
                  <site name="QL_ant_I.3-12.2_r_12.2_r-P2" pos="-0.04024 0.11786 0.04608"/>
                  <site name="QL_ant_I.3-12.3_r_12.3_r-P3" pos="-0.03801 0.111359 0.05452"/>
                  <site name="QL_ant_I.2-T12_l_T12_l-P2" pos="-0.0142008 0.13014 -0.01737"/>
                  <site name="QL_ant_I.3-T12_l_T12_l-P2" pos="-0.0142008 0.13014 -0.01737"/>
                  <site name="QL_ant_I.2-12.1_l_12.1_l-P3" pos="-0.0402807 0.124401 -0.03745"/>
                  <site name="QL_ant_I.3-12.1_l_12.1_l-P2" pos="-0.0402807 0.124401 -0.03745"/>
                  <site name="QL_ant_I.3-12.2_l_12.2_l-P2" pos="-0.04024 0.11786 -0.04608"/>
                  <site name="QL_ant_I.3-12.3_l_12.3_l-P3" pos="-0.03801 0.111359 -0.05452"/>
                  <site name="EO1_r_EO1_r-P2" pos="0.0881973 0.177994 0.0956568"/>
                  <site name="EO2_r_EO2_r-P1" pos="0.0905898 0.14533 0.104779"/>
                  <site name="EO3_r_EO3_r-P1" pos="0.0853701 0.113322 0.108229"/>
                  <site name="EO4_r_EO4_r-P1" pos="0.0745605 0.0914164 0.104112"/>
                  <site name="EO5_r_EO5_r-P1" pos="0.0168281 0.107959 0.117863"/>
                  <site name="EO6_r_EO6_r-P1" pos="-0.00233202 0.0921232 0.105106"/>
                  <site name="IO4_r_IO4_r-P1" pos="0.0769886 0.110032 0.1145"/>
                  <site name="IO5_r_IO5_r-P1" pos="0.03742 0.09485 0.111111"/>
                  <site name="IO6_r_IO6_r-P1" pos="0.00544396 0.0844179 0.1"/>
                  <site name="EO1_l_EO1_l-P2" pos="0.0882 0.177994 -0.09566"/>
                  <site name="EO2_l_EO2_l-P1" pos="0.0905898 0.14533 -0.10478"/>
                  <site name="EO3_l_EO3_l-P1" pos="0.0853701 0.113322 -0.10823"/>
                  <site name="EO4_l_EO4_l-P1" pos="0.0745605 0.0914164 -0.10411"/>
                  <site name="EO5_l_EO5_l-P1" pos="0.0168281 0.107959 -0.11786"/>
                  <site name="EO6_l_EO6_l-P1" pos="-0.00233202 0.0921232 -0.10511"/>
                  <site name="IO4_l_IO4_l-P1" pos="0.0769886 0.110032 -0.1145"/>
                  <site name="IO5_l_IO5_l-P1" pos="0.03742 0.09485 -0.11111"/>
                  <site name="IO6_l_IO6_l-P1" pos="0.00544396 0.0844179 -0.1"/>
                </body>
              </body>
            </body>
          </body>
        </body>
      </body>
    </body>

</mujocoinclude>